Workbook

Sheet Смета
A1: СМ-01. Смета ориентировочная — кв. 108, СПб, вариант D1 (бюджет «Ремонт»)
A2: Цены — ориентировочные для Санкт-Петербурга на 10.2026 (средний сегмент, розница/подрядчики), не являются офертой и подлежат проверке у поставщиков перед закупкой. Материалы — по диапазонам 02-concept/materials.json (price_ref) с поправкой на рост цен 1-го полугодия 2026 (INFOline: плитка +17 %, электрика +15 %, ЛКМ +10 %, напольные +10,5 %); расценки работ — калибровка по открытым прайсам СПб (поиск 2026-10-08, источники в 05-estimate/estimate.md).
A4: Шифр | B4: Этап | C4: Работы, ₽ | D4: Материалы и изделия, ₽ | E4: Итого, ₽ | F4: Доля
A5: Э01 | B5: Демонтаж и подготовка | C5: =SUMIF('Работы'!$A$2:$A$108,A5,'Работы'!$G$2:$G$108) | D5: =SUMIF('Материалы (Ремонт)'!$A$2:$A$275,A5,'Материалы (Ремонт)'!$H$2:$H$275) | E5: =C5+D5 | F5: =E5/$E$19
A6: Э02 | B6: Перегородки, закладки, зашивка окна, каркасные облицовки | C6: =SUMIF('Работы'!$A$2:$A$108,A6,'Работы'!$G$2:$G$108) | D6: =SUMIF('Материалы (Ремонт)'!$A$2:$A$275,A6,'Материалы (Ремонт)'!$H$2:$H$275) | E6: =C6+D6 | F6: =E6/$E$19
A7: Э03 | B7: Утепление и остекление балкона | C7: =SUMIF('Работы'!$A$2:$A$108,A7,'Работы'!$G$2:$G$108) | D7: =SUMIF('Материалы (Ремонт)'!$A$2:$A$275,A7,'Материалы (Ремонт)'!$H$2:$H$275) | E7: =C7+D7 | F7: =E7/$E$19
A8: Э04 | B8: Электромонтаж (черновой), щит, слаботочка, электро-ТП | C8: =SUMIF('Работы'!$A$2:$A$108,A8,'Работы'!$G$2:$G$108) | D8: =SUMIF('Материалы (Ремонт)'!$A$2:$A$275,A8,'Материалы (Ремонт)'!$H$2:$H$275) | E8: =C8+D8 | F8: =E8/$E$19
A9: Э05 | B9: Сантехмонтаж (черновой) и вентиляция | C9: =SUMIF('Работы'!$A$2:$A$108,A9,'Работы'!$G$2:$G$108) | D9: =SUMIF('Материалы (Ремонт)'!$A$2:$A$275,A9,'Материалы (Ремонт)'!$H$2:$H$275) | E9: =C9+D9 | F9: =E9/$E$19
A10: Э06 | B10: Подиум ванной, гидроизоляция, стяжка балкона | C10: =SUMIF('Работы'!$A$2:$A$108,A10,'Работы'!$G$2:$G$108) | D10: =SUMIF('Материалы (Ремонт)'!$A$2:$A$275,A10,'Материалы (Ремонт)'!$H$2:$H$275) | E10: =C10+D10 | F10: =E10/$E$19
A11: Э07 | B11: Штукатурка и шпаклёвка | C11: =SUMIF('Работы'!$A$2:$A$108,A11,'Работы'!$G$2:$G$108) | D11: =SUMIF('Материалы (Ремонт)'!$A$2:$A$275,A11,'Материалы (Ремонт)'!$H$2:$H$275) | E11: =C11+D11 | F11: =E11/$E$19
A12: Э08 | B12: Плиточные работы | C12: =SUMIF('Работы'!$A$2:$A$108,A12,'Работы'!$G$2:$G$108) | D12: =SUMIF('Материалы (Ремонт)'!$A$2:$A$275,A12,'Материалы (Ремонт)'!$H$2:$H$275) | E12: =C12+D12 | F12: =E12/$E$19
A13: Э09 | B13: Потолки ГКЛ, короба, ниши | C13: =SUMIF('Работы'!$A$2:$A$108,A13,'Работы'!$G$2:$G$108) | D13: =SUMIF('Материалы (Ремонт)'!$A$2:$A$275,A13,'Материалы (Ремонт)'!$H$2:$H$275) | E13: =C13+D13 | F13: =E13/$E$19
A14: Э10 | B14: Покраска, молдинги, карнизы, буазери | C14: =SUMIF('Работы'!$A$2:$A$108,A14,'Работы'!$G$2:$G$108) | D14: =SUMIF('Материалы (Ремонт)'!$A$2:$A$275,A14,'Материалы (Ремонт)'!$H$2:$H$275) | E14: =C14+D14 | F14: =E14/$E$19
A15: Э11 | B15: Полы (инженерная доска, LVT) | C15: =SUMIF('Работы'!$A$2:$A$108,A15,'Работы'!$G$2:$G$108) | D15: =SUMIF('Материалы (Ремонт)'!$A$2:$A$275,A15,'Материалы (Ремонт)'!$H$2:$H$275) | E15: =C15+D15 | F15: =E15/$E$19
A16: Э12 | B16: Двери | C16: =SUMIF('Работы'!$A$2:$A$108,A16,'Работы'!$G$2:$G$108) | D16: =SUMIF('Материалы (Ремонт)'!$A$2:$A$275,A16,'Материалы (Ремонт)'!$H$2:$H$275) | E16: =C16+D16 | F16: =E16/$E$19
... A18: Э14 | B18: Вывоз мусора, логистика, уборка | C18: =SUMIF('Работы'!$A$2:$A$108,A18,'Работы'!$G$2:$G$108) | D18: =SUMIF('Материалы (Ремонт)'!$A$2:$A$275,A18,'Материалы (Ремонт)'!$H$2:$H$275) | E18: =C18+D18 | F18: =E18/$E$19
B19: Итого без резерва | C19: =SUM(C5:C18) | D19: =SUM(D5:D18) | E19: =SUM(E5:E18)
B20: Резерв на непредвиденное, % | E20: 0.1
B21: Резерв, ₽ | E21: =E19*E20
B22: ИТОГО «Ремонт» с резервом 10 % | E22: =E19+E21

Sheet Работы
A1: Этап | B1: Поз. | C1: Наименование работ | D1: Ед. | E1: Объём | F1: Расценка, ₽ | G1: Сумма, ₽ | H1: Источник объёма (id / лист) | I1: Расчёт
A2: Э01 | B2: Э01.1 | C2: Тепловизионная съёмка пола при работающем водяном ТП, разметка трасс труб | D2: компл | E2: 1 | F2: 14000 | G2: =E2*F2 | H2: planning.json new_walls_general; D3; №13
A3: Э01 | B3: Э01.2 | C3: Укрытие и защита стяжки с водяным ТП на период работ | D3: м² | E3: 61.7 | F3: 120 | G3: =E3*F3 | H3: planning.json areas.sum_without_balcony
A4: Э01 | B4: Э01.3 | C4: Демонтаж заполнения балконного проёма O4 (блок, порог), без расширения проёма | D4: шт | E4: 1 | F4: 9000 | G4: =E4*F4 | H4: O4-fill; D2; АР-05
A5: Э01 | B5: Э01.4 | C5: Пробивка проёмов в перегородках W12 (D3) и W11 (D4) вручную, без ударного инструмента | D5: м² | E5: 1.35 | F5: 4500 | G5: =E5*F5 | H5: W12-cut, W11-cut; АР-05 | I5: W12 0.61 + W11 0.74
A6: Э01 | B6: Э01.5 | C6: Демонтаж подоконной доски и внутренних откосов O1 | D6: шт | E6: 1 | F6: 2500 | G6: =E6*F6 | H6: O1-infill; АР-05
A7: Э01 | B7: Э01.6 | C7: Демонтаж приборов застройщика (WC постирочной F1 и пр., если установлены), заглушки | D7: компл | E7: 1 | F7: 6000 | G7: =E7*F7 | H7: planning demolition F1, F-all
A8: Э02 | B8: Э02.1 | C8: Кладка ПГП 100 на клей по демпферной ленте (NW1, закладка O9) + ГКЛ на клей со стороны кухни | D8: м² | E8: 4.87 | F8: 2600 | G8: =E8*F8 | H8: NW1; АР-06
A9: Э02 | B9: Э02.2 | C9: Кладка ПГП 80 (NW4 за вычетом проёма D2, добор у D1) | D9: м² | E9: 2.2 | F9: 1700 | G9: =E9*F9 | H9: NW4; elevations R1 W7 добор 199
A10: Э02 | B10: Э02.3 | C10: Кладка ПГП-Г 80 (закладки NW8, NW9) с обмазочной ГИ со стороны с/у | D10: м² | E10: 2.14 | F10: 1900 | G10: =E10*F10 | H10: NW8, NW9
A11: Э02 | B11: Э02.4 | C11: Устройство перемычек над новыми проёмами D3, D4 | D11: шт | E11: 2 | F11: 2000 | G11: =E11*F11 | H11: W12-cut, W11-cut
A12: Э02 | B12: Э02.5 | C12: Зашивка окна O1 изнутри: каркас в откосе, минвата, пароизоляция, 2×ГКЛ (съёмная зона под буазери) | D12: м² | E12: 2.98 | F12: 5000 | G12: =E12*F12 | H12: window_infill O1; узел 8
A13: Э02 | B13: Э02.6 | C13: Облицовка W7 ГКЛ 12,5 на профиле (без штроб в ж/б, D15, D23) | D13: м² | E13: 11.05 | F13: 1100 | G13: =E13*F13 | H13: walls R1 gkl_cladding; АР-15
A14: Э02 | B14: Э02.7 | C14: Облицовка W14 в душе VK-C1: каркас + 2×ГВЛВ, к стене и потолку (без крепления в пол), ниши 2 шт | D14: м² | E14: 2.29 | F14: 3500 | G14: =E14*F14 | H14: VK-C1; узел 11
A15: Э02 | B15: Э02.8 | C15: Короб инсталляции с полкой h 1200 (2×ГВЛВ) | D15: шт | E15: 1 | F15: 6500 | G15: =E15*F15 | H15: F69; АР-13
A16: Э02 | B16: Э02.9 | C16: Короб-перемычка VK-C2 h 450 и экран ванны на каркасе с ревизией H6 | D16: м² | E16: 1.68 | F16: 3000 | G16: =E16*F16 | H16: VK-C2; экран ванны; H6
A17: Э02 | B17: Э02.10 | C17: Закладные под люстры, подвесы, проектор, ДСК, сушилку, карниз с приводом | D17: шт | E17: 7 | F17: 1500 | G17: =E17*F17 | H17: finish-quantities counts
... A23: Э04 | B23: Э04.2 | C23: Сборка щита: установка и расключение модульных аппаратов, маркировка | D23: модуль | E23: 32 | F23: 1000 | G23: =E23*F23 | H23: panel.json modules_used
A24: Э04 | B24: Э04.3 | C24: Прокладка силового кабеля в гофре по потолку (с креплением) | D24: м | E24: 681.49 | F24: 110 | G24: =E24*F24 | H24: panel.json Σ length_m × 1,15 | I24: 592.6 × 1,15
A25: Э04 | B25: Э04.4 | C25: Прокладка слаботочных кабелей (Cat6, RG-6, акустика, датчики, краны, AV) | D25: м | E25: 186.02 | F25: 110 | G25: =E25*F25 | H25: electrical.json low_voltage (трассы по координатам)
A26: Э04 | B26: Э04.5 | C26: Штробление вертикальное ≤ 25 мм (кирпич) с заделкой / спуски в облицовках | D26: м | E26: 119.83 | F26: 600 | G26: =E26*F26 | H26: sockets + switches: (потолок − h) | I26: Σ спусков к точкам
A27: Э04 | B27: Э04.6 | C27: Установка подрозетника (высверливание в кирпиче/ГКЛ), монтаж точки | D27: шт | E27: 87 | F27: 550 | G27: =E27*F27 | H27: посты sockets + switches
A28: Э04 | B28: Э04.7 | C28: Вывод под светильник / ленту (кабель, коробка, маркировка) | D28: шт | E28: 42 | F28: 450 | G28: =E28*F28 | H28: electrical.json lights
A29: Э04 | B29: Э04.8 | C29: Укладка нагревательных матов в клей с датчиком пола (TP1–TP3) | D29: м² | E29: 5.27 | F29: 1300 | G29: =E29*F29 | H29: heating.json; ОВ-01
A30: Э04 | B30: Э04.9 | C30: ДУП ванной и постирочной (КУП, ПуГВ 4 мм²) | D30: шт | E30: 2 | F30: 3500 | G30: =E30*F30 | H30: panel.json rcd_policy
A31: Э04 | B31: Э04.10 | C31: Монтаж СС-щита U16, расшивка патч-панели, тестирование линий | D31: компл | E31: 1 | F31: 9000 | G31: =E31*F31 | H31: U16; LV00
A32: Э04 | B32: Э04.11 | C32: Электролаборатория: измерения, протокол | D32: компл | E32: 1 | F32: 15000 | G32: =E32*F32 | H32: ЭМ-03
A33: Э05 | B33: Э05.1 | C33: Сборка узла ввода (краны, фильтр-редуктор, счётчики, обр. клапан, электрокраны, коллекторы) | D33: узел | E33: 2 | F33: 16000 | G33: =E33*F33 | H33: N1, N2; ВК-03
A34: Э05 | B34: Э05.2 | C34: Разводка водоснабжения PEX-a до водорозетки (трасса + вывод) | D34: вывод | E34: 12 | F34: 3200 | G34: =E34*F34 | H34: pipes.water WB1–WL2
A35: Э05 | B35: Э05.3 | C35: Разводка канализации ПП к прибору с уклоном (трасса + вывод) | D35: вывод | E35: 7 | F35: 2900 | G35: =E35*F35 | H35: pipes.sewer S1–S7; calc_sewer_slopes.py
A36: Э05 | B36: Э05.4 | C36: Монтаж инсталляции (рама к стене, D3) | D36: шт | E36: 1 | F36: 7000 | G36: =E36*F36 | H36: F69; P01
A37: Э05 | B37: Э05.5 | C37: Монтаж линейного трапа низкого (h ≤ 70) с фланцем | D37: шт | E37: 1 | F37: 7500 | G37: =E37*F37 | H37: F67; S1; узел 7
A38: Э05 | B38: Э05.6 | C38: Монтаж скрытой части термостата душа в облицовке VK-C1 | D38: шт | E38: 1 | F38: 6000 | G38: =E38*F38 | H38: P04; WB3
... A43: Э05 | B43: Э05.11 | C43: Алмазное бурение Ø132 в наружной стене 420 под бризеры | D43: шт | E43: 2 | F43: 6500 | G43: =E43*F43 | H43: BR1, BR2
A44: Э06 | B44: Э06.1 | C44: Гидроизоляция обмазочная 2 слоя с лентами (пол R5 — нижняя + основная, пол R6, стены) | D44: м² | E44: 26.56 | F44: 1000 | G44: =E44*F44 | H44: floors waterproofing_floor; waterproofing_walls | I44: R5 5.17×2 + R6 3.12 + стены 13.1
A45: Э06 | B45: Э06.2 | C45: Подиум ванной ЦПС 78,5 мм армированный, уклон 1,5 % к трапу | D45: м² | E45: 5.1 | F45: 2500 | G45: =E45*F45 | H45: floors podium_screed_80; D18
A46: Э06 | B46: Э06.3 | C46: Рамка-бортик коллектора U14 | D46: шт | E46: 1 | F46: 4000 | G46: =E46*F46 | H46: VK-C3; узел 6
A47: Э06 | B47: Э06.4 | C47: Пол балкона: ремонт плиты, XPS 50, ПЭ-плёнка, демпферная лента | D47: м² | E47: 6.86 | F47: 900 | G47: =E47*F47 | H47: P-BALC; D22
A48: Э06 | B48: Э06.5 | C48: Стяжка балкона ЦПС 55 армированная + СВС 10 по мату TP3 | D48: м² | E48: 6.86 | F48: 1900 | G48: =E48*F48 | H48: P-BALC
A49: Э07 | B49: Э07.1 | C49: Штукатурка стен по маякам (гипсовая), ср. 15 мм | D49: м² | E49: 118.4 | F49: 750 | G49: =E49*F49 | H49: walls (gross − проёмы, без облицовок)
...

Sheet Материалы (Ремонт)
A1: Этап | B1: Спецификация | C1: Поз. | D1: Наименование | E1: Кол-во | F1: Ед. | G1: Цена, ₽ | H1: Сумма, ₽ | I1: Помещение | J1: Ссылка (лист / id)
A2: Э10 | B2: СП-02.1 | C2: 1 | D2: Буазери стены-изголовья W2 2,9×2,7 м: МДФ 16–19, рамки 25–40, центральная филёнка 1860×1600 съёмная, эмаль C3 | E2: 1 | F2: компл | G2: 95000 | H2: =E2*G2 | I2: R1 | J2: F41; АР-15; M06; узел 8
A3: Э13 | B3: СП-02.1 | C3: 2 | D3: Шкаф-купе Г 2480+745×600 до потолка: корпус ЛДСП E1, двери — рамочный профиль + вставки МДФ эмаль C3 с накладной филёнкой, верхний подвес | E3: 1 | F3: компл | G3: 215000 | H3: =E3*G3 | I3: R1 | J3: F45, F46; M07
A4: Э13 | B4: СП-02.1 | C4: 3 | D4: Шкаф прихожей 2720×600×2650: 3 секции по 900, 6 распашных фасадов МДФ эмаль C2 с рамкой-филёнкой, дверь-зеркало, ниша робота | E4: 1 | F4: компл | G4: 195000 | H4: =E4*G4 | I4: R4 | J4: F60, F61, F62; M17; АР-12
A5: Э13 | B5: СП-02.1 | C5: 4 | D5: Системы хранения постирочной: тумба хозмойки 450, карго 300, столешница компакт-плита 12 мм 770×600, навесные 350, пенал 540, антресоль 650, шкафы 350 у W10 (фасады от пола без дна над U11) | E5: 1 | F5: компл | G5: 115000 | H5: =E5*G5 | I5: R6 | J5: F78, F79, F83, F84, F85, F86, F87, F88; M26; АР-14
A6: Э13 | B6: СП-02.1 | C6: 5 | D6: Сушилка потолочная «лиана» 4 прутка | E6: 1 | F6: шт | G6: 4500 | H6: =E6*G6 | I6: R6 | J6: F89
A7: Э13 | B7: СП-03.1 | C7: 1 | D7: Спот встраиваемый LED 7 Вт, 2700 K, CRI ≥ 90, диммируемый, глубина ≤ 80 — группа L2 | E7: 4 | F7: шт | G7: 2700 | H7: =E7*G7 | I7: R3 | J7: L2-1, L2-2, L2-3, L2-4; ЭО-01
A8: Э13 | B8: СП-03.1 | C8: 2 | D8: Люстра столовой 5–6 рожков LED, латунь сатин/ткань, диммируемая — группа L3 | E8: 1 | F8: шт | G8: 32000 | H8: =E8*G8 | I8: R3 | J8: L3-1; ЭО-01
A9: Э13 | B9: СП-03.1 | C9: 3 | D9: Бра латунь сатин C8 с абажуром — группа L4 | E9: 2 | F9: шт | G9: 9500 | H9: =E9*G9 | I9: R3 | J9: L4-1, L4-2; ЭО-01
A10: Э13 | B10: СП-03.1 | C10: 4 | D10: Спот встраиваемый LED 7 Вт, 2700 K, CRI ≥ 90, диммируемый, глубина ≤ 80 — группа L6 | E10: 4 | F10: шт | G10: 2700 | H10: =E10*G10 | I10: R7 | J10: L6-1, L6-2, L6-3, L6-4; ЭО-01
A11: Э13 | B11: СП-03.1 | C11: 5 | D11: Люстра спальни, диммируемая, латунь/ткань — группа L8 | E11: 1 | F11: шт | G11: 24000 | H11: =E11*G11 | I11: R1 | J11: L8-1; ЭО-01
A12: Э13 | B12: СП-03.1 | C12: 6 | D12: Бра латунь сатин C8 с абажуром — группа L11 | E12: 2 | F12: шт | G12: 9500 | H12: =E12*G12 | I12: R1 | J12: L11-1, L11-2; F41; ЭО-01
A13: Э13 | B13: СП-03.1 | C13: 7 | D13: Светильник потолочный рассеянный детской, диммируемый — группа L14 | E13: 1 | F13: шт | G13: 14000 | H13: =E13*G13 | I13: R2 | J13: L14-1; ЭО-01
... A78: Э04 | B78: СП-03.3 | C78: 12 | D78: Шины N/PE, гребёнки, заглушки, маркировка, DIN-розетки ×3 (P-SS1 в U16) | E78: 1 | F78: компл | G78: 6500 | H78: =E78*G78 | I78: R4 | J78: panel.json; P-SS1
A79: Э04 | B79: СП-03.3 | C79: 13 | D79: Кабель ВВГнг(А)-LS 3×1,5 | E79: =CEILING(240.6*1.15,5) | F79: м | G79: 115 | H79: =E79*G79 | I79: все | J79: C1, C2, C3; panel.json length_m
A80: Э04 | B80: СП-03.3 | C80: 14 | D80: Кабель ВВГнг(А)-LS 3×2,5 | E80: =CEILING(338.8*1.15,5) | F80: м | G80: 170 | H80: =E80*G80 | I80: все | J80: C4, C5, C6, C8, C9, C10, C11, C12, C13, C14, C15, C16, C17, C18, C19, C20, C21, C22; panel.json length_m
A81: Э04 | B81: СП-03.3 | C81: 15 | D81: Кабель ВВГнг(А)-LS 3×6 | E81: =CEILING(13.2*1.15,5) | F81: м | G81: 430 | H81: =E81*G81 | I81: все | J81: C7; panel.json length_m
A82: Э04 | B82: СП-03.3 | C82: 16 | D82: Труба гофрированная ПВХ нг Ø20 с зондом (по потолку, D15) | E82: 700 | F82: м | G82: 28 | H82: =E82*G82 | I82: все | J82: panel.json Σ length_m × 1,15
A83: Э04 | B83: СП-03.3 | C83: 17 | D83: Провод ПуГВ 1×4 + коробки КУП (ДУП ванной и постирочной) | E83: 2 | F83: компл | G83: 1800 | H83: =E83*G83 | I83: R5, R6 | J83: panel.json rcd_policy (ДУП)
A84: Э04 | B84: СП-03.3 | C84: 18 | D84: Крепёж кабеля: клипсы, дюбель-хомуты, распаечные коробки (доступные), клеммы Wago | E84: 1 | F84: компл | G84: 9000 | H84: =E84*G84 | I84: все | J84: 23 групп
A85: Э13 | B85: СП-04 | C85: 1 | D85: Ванна 1700×750 акрил усиленный/кварил, ножки, экран — облицовка плиткой с ревизией H6 | E85: 1 | F85: шт | G85: 42000 | H85: =E85*G85 | I85: R5 | J85: F66; P03; M24
A86: Э13 | B86: СП-04 | C86: 2 | D86: Сифон-автомат ванны с переливом (выпуск у правого торца) | E86: 1 | F86: шт | G86: 6500 | H86: =E86*G86 | I86: R5 | J86: P03; S2
A87: Э13 | B87: СП-04 | C87: 3 | D87: Смеситель для ванны настенный, латунь браш C8 | E87: 1 | F87: шт | G87: 18000 | H87: =E87*G87 | I87: R5 | J87: P03; WB4
A88: Э05 | B88: СП-04 | C88: 4 | D88: Термостат скрытого монтажа на 2 потребителя (встраиваемая часть + лицевая панель), латунь браш | E88: 1 | F88: компл | G88: 38000 | H88: =E88*G88 | I88: R5 | J88: P04; WB3; D23
A89: Э13 | B89: СП-04 | C89: 5 | D89: Верхний душ 250 + кронштейн, ручной душ со шлангом и подключением, латунь браш | E89: 1 | F89: компл | G89: 20000 | H89: =E89*G89 | I89: R5 | J89: P04
A90: Э05 | B90: СП-04 | C90: 6 | D90: Трап линейный низкий 800, h ≤ 70, под плитку, с гидрозатвором и фланцем ГИ | E90: 1 | F90: шт | G90: 16000 | H90: =E90*G90 | I90: R5 | J90: F67; P04; S1; узел 7; D18
A91: Э13 | B91: СП-04 | C91: 7 | D91: Стекло душа фиксированное 315×2000, 8 мм, профиль на клею, стабилизатор к потолку (латунь) | E91: 1 | F91: компл | G91: 22000 | H91: =E91*G91 | I91: R5 | J91: F68
A92: Э05 | B92: СП-04 | C92: 8 | D92: Инсталляция для подвесного унитаза (рама к стене, D3) | E92: 1 | F92: шт | G92: 28000 | H92: =E92*G92 | I92: R5 | J92: F69; P01
A93: Э13 | B93: СП-04 | C93: 9 | D93: Кнопка смыва, латунь браш | E93: 1 | F93: шт | G93: 7000 | H93: =E93*G93 | I93: R5 | J93: F69; P01
... A151: Э12 | B151: СП-02.3 | C151: 27 | D151: Наличник C1 изнутри входной двери ДВ-1 (комплект с цоколем) | E151: 1 | F151: компл | G151: 8000 | H151: =E151*G151 | I151: R4 | J151: O5; ДВ-1
A152: Э11 | B152: СП-05 | C152: 1 | D152: Инженерная доска дуб 2-слойная 14–15 мм, ёлочка 90×600, ультраматовый лак, допуск на водяной ТП | E152: =CEILING(51.45*1.08,1.0) | F152: м² | G152: 7800 | H152: =E152*G152 | I152: R1, R2, R3, R4 | J152: floors oak_herringbone (R1 17,54, R2 11,87, R3 14,59, R4 7,45); M01; АР-10
A153: Э11 | B153: СП-05 | C153: 2 | D153: Клей паркетный MS-полимер эластичный (1,2 кг/м²) | E153: =CEILING(51.45*1.2,15) | F153: кг | G153: 700 | H153: =E153*G153 | I153: R1, R2, R3, R4 | J153: P-OAK; M01
A154: Э11 | B154: СП-05 | C154: 3 | D154: Грунт/ремонтный состав под клей (0,2 л/м²) и локальный ремонт стяжки | E154: 15 | F154: л | G154: 950 | H154: =E154*G154 | I154: R1, R2, R3, R4 | J154: P-OAK
A155: Э11 | B155: СП-05 | C155: 4 | D155: LVT клеевой «ёлочка» в тон дуба C7, 33/42 кл., слой износа ≥ 0,55, допуск на ТП | E155: =CEILING(6.47*1.08,0.5) | F155: м² | G155: 3300 | H155: =E155*G155 | I155: R7 | J155: floors lvt_herringbone; M28
A156: Э11 | B156: СП-05 | C156: 5 | D156: Клей дисперсионный для LVT (0,35 кг/м²) | E156: 3 | F156: кг | G156: 450 | H156: =E156*G156 | I156: R7 | J156: P-BALC; M28
A157: Э08 | B157: СП-05 | C157: 6 | D157: Керамогранит 60×60 «светлый камень» R10 ректификат (вход) | E157: =CEILING(1.89*1.1,1.44) | F157: м² | G157: 3900 | H157: =E157*G157 | I157: R4 | J157: floors porcelain_60x60_hall; M16
A158: Э08 | B158: СП-05 | C158: 7 | D158: Керамогранит 60×60 «светлый мрамор» R10 ректификат (ванная, постирочная) | E158: =CEILING(5.85*1.1,1.44) | F158: м² | G158: 4500 | H158: =E158*G158 | I158: R5, R6 | J158: floors porcelain_60x60_bath + _laundry; M20, M25
A159: Э08 | B159: СП-05 | C159: 8 | D159: Керамогранит 60×120 «светлый мрамор» R10/B (пол душа, уклон к трапу) | E159: =CEILING(0.71*1.15,1.44) | F159: м² | G159: 5900 | H159: =E159*G159 | I159: R5 | J159: floors porcelain_60x120_shower_R10B; M20
A160: Э08 | B160: СП-05 | C160: 9 | D160: Керамогранит 60×120 «светлый мрамор» матовый — стены ванной (мокрые зоны до потолка + до +1280) и фартук кухни | E160: =CEILING(18.3*1.15,1.44) | F160: м² | G160: 5600 | H160: =E160*G160 | I160: R5, R3 | J160: walls tile_wet + tile_dry + tile_apron_porcelain; M21, M13; АР-13, АР-11
A161: Э08 | B161: СП-05 | C161: 10 | D161: Плитка «кабанчик» матовая (фартук хозмойки) | E161: =CEILING(0.77*1.1,1.0) | F161: м² | G161: 2600 | H161: =E161*G161 | I161: R6 | J161: walls tile_apron; M27; АР-14
...

Sheet Мебель и техника
A1: Спецификация | B1: Поз. | C1: Наименование | D1: Кол-во | E1: Ед. | F1: Цена, ₽ | G1: Сумма, ₽ | H1: Помещение | I1: Ссылка
A2: СП-02.1 | B2: 6 | C2: Стол обеденный 1800×900 (шпон дуба/массив) | D2: 1 | E2: шт | F2: 50000 | G2: =D2*F2 | H2: R3 | I2: F25
A3: СП-02.1 | B3: 7 | C3: Стул мягкий (рогожка/велюр, каркас бук) | D3: 6 | E3: шт | F3: 11000 | G3: =D3*F3 | H3: R3 | I3: F26, F27, F28, F29, F30, F31
A4: СП-02.1 | B4: 8 | C4: П-диван по размеру: спинная секция 3023×750 + 2 боковые 650×700 (отсек AV), съёмные чехлы, на ножках | D4: 1 | E4: компл | F4: 155000 | G4: =D4*F4 | H4: R7 | I4: F33, F34, F35
A5: СП-02.1 | B5: 9 | C5: Пуф-стол 500×800 | D5: 1 | E5: шт | F5: 18000 | G5: =D5*F5 | H5: R7 | I5: F36
A6: СП-02.1 | B6: 10 | C6: Кровать 1800×2000 с мягким изголовьем, рама на глайдерах | D6: 1 | E6: шт | F6: 75000 | G6: =D6*F6 | H6: R1 | I6: F42
A7: СП-02.1 | B7: 11 | C7: Матрас 1800×2000 средней жёсткости | D7: 1 | E7: шт | F7: 40000 | G7: =D7*F7 | H7: R1 | I7: F42
A8: СП-02.1 | B8: 12 | C8: Тумба прикроватная подвесная 450×500 | D8: 2 | E8: шт | F8: 9000 | G8: =D8*F8 | H8: R1 | I8: F43, F44
A9: СП-02.1 | B9: 13 | C9: ТВ-консоль подвесная 1600×300 МДФ эмаль, низ +250 | D9: 1 | E9: шт | F9: 32000 | G9: =D9*F9 | H9: R1 | I9: F47
A10: СП-02.1 | B10: 14 | C10: Стол рабочий 1400×600, столешница дуб, консоль/подстолье к стене | D10: 1 | E10: шт | F10: 35000 | G10: =D10*F10 | H10: R1 | I10: F49
A11: СП-02.1 | B11: 15 | C11: Кресло рабочее эргономичное | D11: 1 | E11: шт | F11: 18000 | G11: =D11*F11 | H11: R1 | I11: F50
A12: СП-02.1 | B12: 16 | C12: Шкаф детский 1800×600×2400, 2 секции, распашной, крепление к стене | D12: 1 | E12: шт | F12: 38000 | G12: =D12*F12 | H12: R2 | I12: F52
A13: СП-02.1 | B13: 17 | C13: Кровать детская 900×2000 с ящиками для игрушек | D13: 1 | E13: шт | F13: 28000 | G13: =D13*F13 | H13: R2 | I13: F53
... A52: СП-03.4 | B52: 31 | C52: Телевизор 65″ 4K + плоский кронштейн | D52: 1 | E52: компл | F52: 65000 | G52: =D52*F52 | H52: R1 | I52: F48; D12
C53: Итого без резерва | G53: =SUM(G2:G52)
C54: Резерв 10 % | G54: =G53*0.1
C55: ИТОГО «Мебель+техника» с резервом | G55: =G53+G54

Sheet Бюджеты
A1: Сверка с бюджетом брифа (границы бюджетов — questions.md №34)
A3: Бюджет | B3: Лимит брифа, ₽ | C3: Смета без резерва, ₽ | D3: Смета с резервом 10 %, ₽ | E3: Отклонение (с резервом), ₽ | F3: Отклонение, % | G3: Отклонение без резерва, ₽
A4: Ремонт (работы + материалы + сантехника + свет + двери + встроенные шкафы + остекление/утепление балкона) | B4: 5000000 | C4: ='Смета'!E19 | D4: ='Смета'!E22 | E4: =D4-B4 | F4: =E4/B4 | G4: =C4-B4
A5: Мебель + техника (кухня, бытовая техника, проектор/экран/акустика, ТВ, диваны, кровати, мебель детской) | B5: 1500000 | C5: ='Мебель и техника'!G53 | D5: ='Мебель и техника'!G55 | E5: =D5-B5 | F5: =E5/B5 | G5: =C5-B5
A6: ВСЕГО | B6: =SUM(B4:B5) | C6: =SUM(C4:C5) | D6: =SUM(D4:D5) | E6: =SUM(E4:E5) | F6: =E6/B6 | G6: =SUM(G4:G5)
A8: Положительное отклонение — превышение бюджета; меры — 05-estimate/value-engineering.md.

Sheet Источники и допущения
A1: Дата поиска: 2026-10-08. Сайты подрядчиков часть прайсов отдают только в выдаче (прямой доступ из среды закрыт) — цифры взяты из сниппетов поисковой выдачи и использованы как калибровка диапазона, не как точная цена.
A2: - INFOline / RBC Retail: рост цен на стройматериалы в СПб, 1-е полугодие 2026 (плитка +17,3 %, электрика +15,3 %, напольные +10,5 %, ЛКМ +10,4 %, сухие смеси +4,7 %): https://www.retail.ru/rbc/pressreleases/keramicheskaya-plitka-vnov-bet-rekord-po-rostu-tsen-v-2026-godu-otmechayut-v-infoline/
A3: - Прайсы отделочных работ СПб 2026 (покраска 450–975 ₽/м², шпаклёвка 2 сл. 495–1 155 ₽/м², плитка 800–5 500 ₽/м²): remontvspb.ru: https://remontvspb.ru/prajs/
A4: - prorabneva.ru — цены на ремонт квартир в СПб 2026: https://www.prorabneva.ru/price
A5: - len-rem.ru — расценки на отделочные работы 2026: https://len-rem.ru/rascenki-na-otdelochnye-raboty.html
A6: - remont-na5.ru — плиточные (Эконом 1 750 / Стандарт 2 800 ₽/м²) и малярные работы СПб: https://remont-na5.ru/uslugi/ukladka-plitki/
A7: - stroikaspb.com — расценки на плиточные работы СПб: https://www.stroikaspb.com/plitochnie-raboti-vspb/
A8: - hands.ru — прайс-лист на отделочные работы в СПб 2026: https://hands.ru/saint-petersburg/category/otdelka/price/
A9: - Profi.ru — установка трапов в СПб (от 1 000 ₽/шт), услуги сантехников: https://profi.ru/geo-spb/remont/santehnika/price/
A10: - Sostav.ru — рейтинг компаний и цены ремонта СПб 2026 (ориентир Москва: работы 18–35 тыс. ₽/м²): https://www.sostav.ru/blogs/286041/75556
A11: - Яндекс Карты — Coswick СПб, инженерная доска (≈ 9 000–11 100 ₽ за позицию): https://yandex.com.tr/maps/org/coswick/20770661221/prices/
A13: Допущения сметы:
... A17: - Количества — tools/gen_specs.py из слоёв 03-drawings/*.json и 04-specs/finish-quantities.json; запасы — в спецификациях.
