Workbook

Sheet Свод
A1: Сводная спецификация — кв. 108, вариант D1
A2: Цены — ориентировочные для Санкт-Петербурга на 10.2026 (средний сегмент, розница/подрядчики), не являются офертой и подлежат проверке у поставщиков перед закупкой. Материалы — по диапазонам 02-concept/materials.json (price_ref) с поправкой на рост цен 1-го полугодия 2026 (INFOline: плитка +17 %, электрика +15 %, ЛКМ +10 %, напольные +10,5 %); расценки работ — калибровка по открытым прайсам СПб (поиск 2026-10-08, источники в 05-estimate/estimate.md).
A4: Шифр | B4: Спецификация (лист) | C4: Итого, ₽ | D4: «Ремонт», ₽ | E4: «Мебель+техника», ₽
A5: СП-02.1 | B5: СП-02.1 Мебель встроенная и отд | C5: =SUM('СП-02.1 Мебель встроенная и отд'!H5:H29) | D5: =SUMIF('СП-02.1 Мебель встроенная и отд'!K5:K29,"Ремонт",'СП-02.1 Мебель встроенная и отд'!H5:H29) | E5: =SUMIF('СП-02.1 Мебель встроенная и отд'!K5:K29,"Мебель+техника",'СП-02.1 Мебель встроенная и отд'!H5:H29)
A6: СП-02.2 | B6: СП-02.2 Кухня и бытовая техника | C6: =SUM('СП-02.2 Кухня и бытовая техника'!H5:H28) | D6: =SUMIF('СП-02.2 Кухня и бытовая техника'!K5:K28,"Ремонт",'СП-02.2 Кухня и бытовая техника'!H5:H28) | E6: =SUMIF('СП-02.2 Кухня и бытовая техника'!K5:K28,"Мебель+техника",'СП-02.2 Кухня и бытовая техника'!H5:H28)
A7: СП-03.1 | B7: СП-03.1 Светильники | C7: =SUM('СП-03.1 Светильники'!H5:H50) | D7: =SUMIF('СП-03.1 Светильники'!K5:K50,"Ремонт",'СП-03.1 Светильники'!H5:H50) | E7: =SUMIF('СП-03.1 Светильники'!K5:K50,"Мебель+техника",'СП-03.1 Светильники'!H5:H50)
A8: СП-03.2 | B8: СП-03.2 Электроустановочные изд | C8: =SUM('СП-03.2 Электроустановочные изд'!H5:H18) | D8: =SUMIF('СП-03.2 Электроустановочные изд'!K5:K18,"Ремонт",'СП-03.2 Электроустановочные изд'!H5:H18) | E8: =SUMIF('СП-03.2 Электроустановочные изд'!K5:K18,"Мебель+техника",'СП-03.2 Электроустановочные изд'!H5:H18)
A9: СП-03.3 | B9: СП-03.3 Щит ЭМ-03 и кабельная п | C9: =SUM('СП-03.3 Щит ЭМ-03 и кабельная п'!H5:H22) | D9: =SUMIF('СП-03.3 Щит ЭМ-03 и кабельная п'!K5:K22,"Ремонт",'СП-03.3 Щит ЭМ-03 и кабельная п'!H5:H22) | E9: =SUMIF('СП-03.3 Щит ЭМ-03 и кабельная п'!K5:K22,"Мебель+техника",'СП-03.3 Щит ЭМ-03 и кабельная п'!H5:H22)
A10: СП-04 | B10: СП-04 Сантехника, мебель ванной | C10: =SUM('СП-04 Сантехника, мебель ванной'!H5:H44) | D10: =SUMIF('СП-04 Сантехника, мебель ванной'!K5:K44,"Ремонт",'СП-04 Сантехника, мебель ванной'!H5:H44) | E10: =SUMIF('СП-04 Сантехника, мебель ванной'!K5:K44,"Мебель+техника",'СП-04 Сантехника, мебель ванной'!H5:H44)
A11: СП-02.3 | B11: СП-02.3 Двери и фурнитура | C11: =SUM('СП-02.3 Двери и фурнитура'!H5:H31) | D11: =SUMIF('СП-02.3 Двери и фурнитура'!K5:K31,"Ремонт",'СП-02.3 Двери и фурнитура'!H5:H31) | E11: =SUMIF('СП-02.3 Двери и фурнитура'!K5:K31,"Мебель+техника",'СП-02.3 Двери и фурнитура'!H5:H31)
A12: СП-05 | B12: СП-05 Отделочные и черновые мат | C12: =SUM('СП-05 Отделочные и черновые мат'!H5:H86) | D12: =SUMIF('СП-05 Отделочные и черновые мат'!K5:K86,"Ремонт",'СП-05 Отделочные и черновые мат'!H5:H86) | E12: =SUMIF('СП-05 Отделочные и черновые мат'!K5:K86,"Мебель+техника",'СП-05 Отделочные и черновые мат'!H5:H86)
A13: СП-04.2 | B13: СП-04.2 Тёплые полы (электро) и | C13: =SUM('СП-04.2 Тёплые полы (электро) и'!H5:H22) | D13: =SUMIF('СП-04.2 Тёплые полы (электро) и'!K5:K22,"Ремонт",'СП-04.2 Тёплые полы (электро) и'!H5:H22) | E13: =SUMIF('СП-04.2 Тёплые полы (электро) и'!K5:K22,"Мебель+техника",'СП-04.2 Тёплые полы (электро) и'!H5:H22)
A14: СП-03.4 | B14: СП-03.4 Слаботочные сети, умный | C14: =SUM('СП-03.4 Слаботочные сети, умный'!H5:H35) | D14: =SUMIF('СП-03.4 Слаботочные сети, умный'!K5:K35,"Ремонт",'СП-03.4 Слаботочные сети, умный'!H5:H35) | E14: =SUMIF('СП-03.4 Слаботочные сети, умный'!K5:K35,"Мебель+техника",'СП-03.4 Слаботочные сети, умный'!H5:H35)
B15: ИТОГО по спецификациям | C15: =SUM(C5:C14) | D15: =SUM(D5:D14) | E15: =SUM(E5:E14)
B17: Работы — в 05-estimate/estimate.xlsx; спецификации содержат только изделия и материалы.

Sheet СП-02.1 Мебель встроенная и отд
A1: СП-02.1. Мебель встроенная и отдельностоящая
A2: Цены — ориентировочные для Санкт-Петербурга на 10.2026 (средний сегмент, розница/подрядчики), не являются офертой и подлежат проверке у поставщиков перед закупкой. Материалы — по диапазонам 02-concept/materials.json (price_ref) с поправкой на рост цен 1-го полугодия 2026 (INFOline: плитка +17 %, электрика +15 %, ЛКМ +10 %, напольные +10,5 %); расценки работ — калибровка по открытым прайсам СПб (поиск 2026-10-08, источники в 05-estimate/estimate.md).
A4: Поз. | B4: Наименование | C4: Артикул / пример | D4: Производитель | E4: Кол-во | F4: Ед. | G4: Цена ориент., ₽ | H4: Сумма, ₽ | I4: Помещение | J4: Ссылка (лист / id) | K4: Бюджет | L4: Этап сметы | M4: Примечание / расчёт кол-ва
A5: 1 | B5: Буазери стены-изголовья W2 2,9×2,7 м: МДФ 16–19, рамки 25–40, центральная филёнка 1860×1600 съёмная, эмаль C3 | C5: по эскизу moodboard.html, схема 1 | D5: мебельный/столярный цех СПб | E5: 1 | F5: компл | G5: 95000 | H5: =E5*G5 | I5: R1 | J5: F41; АР-15; M06; узел 8 | K5: Ремонт | L5: Э10 | M5: под ключ с окраской; зашивка O1 — в работах/СП-05
A6: 2 | B6: Шкаф-купе Г 2480+745×600 до потолка: корпус ЛДСП E1, двери — рамочный профиль + вставки МДФ эмаль C3 с накладной филёнкой, верхний подвес | C6: Aristo/Командор, корпус Egger | D6: мебельный цех СПб | E6: 1 | F6: компл | G6: 215000 | H6: =E6*G6 | I6: R1 | J6: F45, F46; M07 | K6: Ремонт | L6: Э13 | M6: под ключ; подсветка L13 — СП-03.1
A7: 3 | B7: Шкаф прихожей 2720×600×2650: 3 секции по 900, 6 распашных фасадов МДФ эмаль C2 с рамкой-филёнкой, дверь-зеркало, ниша робота | C7: по эскизу moodboard.html, схема 2 | D7: мебельный цех СПб, фурнитура Blum/Hettich | E7: 1 | F7: компл | G7: 195000 | H7: =E7*G7 | I7: R4 | J7: F60, F61, F62; M17; АР-12 | K7: Ремонт | L7: Э13 | M7: под ключ; h 2650 (D19)
A8: 4 | B8: Системы хранения постирочной: тумба хозмойки 450, карго 300, столешница компакт-плита 12 мм 770×600, навесные 350, пенал 540, антресоль 650, шкафы 350 у W10 (фасады от пола без дна над U11) | C8: Egger U702 ST9 «Кашемир серый», кромка ПВХ 2 | D8: мебельный цех СПб | E8: 1 | F8: компл | G8: 115000 | H8: =E8*G8 | I8: R6 | J8: F78, F79, F83, F84, F85, F86, F87, F88; M26; АР-14 | K8: Ремонт | L8: Э13 | M8: под ключ
A9: 5 | B9: Сушилка потолочная «лиана» 4 прутка | C9: ручная, 4 прутка | D9: Гимли/Лиана-класс | E9: 1 | F9: шт | G9: 4500 | H9: =E9*G9 | I9: R6 | J9: F89 | K9: Ремонт | L9: Э13
A10: 6 | B10: Стол обеденный 1800×900 (шпон дуба/массив) | C10: M15 | D10: Stool Group / Woodville / Ellipsefurniture | E10: 1 | F10: шт | G10: 50000 | H10: =E10*G10 | I10: R3 | J10: F25 | K10: Мебель+техника | L10: —
A11: 7 | B11: Стул мягкий (рогожка/велюр, каркас бук) | C11: M15 | D11: Stool Group / Woodville | E11: 6 | F11: шт | G11: 11000 | H11: =E11*G11 | I11: R3 | J11: F26, F27, F28, F29, F30, F31 | K11: Мебель+техника | L11: —
A12: 8 | B12: П-диван по размеру: спинная секция 3023×750 + 2 боковые 650×700 (отсек AV), съёмные чехлы, на ножках | C12: M31 | D12: мастерская СПб по размеру / модульный | E12: 1 | F12: компл | G12: 155000 | H12: =E12*G12 | I12: R7 | J12: F33, F34, F35 | K12: Мебель+техника | L12: — | M12: встроенные блоки розеток P-B03a/P-B04a/b — поставка с диваном
A13: 9 | B13: Пуф-стол 500×800 | C13: M31 | D13: мастерская (с диваном) | E13: 1 | F13: шт | G13: 18000 | H13: =E13*G13 | I13: R7 | J13: F36 | K13: Мебель+техника | L13: —
A14: 10 | B14: Кровать 1800×2000 с мягким изголовьем, рама на глайдерах | C14: M09 | D14: Askona / Ormatek / Dreamline | E14: 1 | F14: шт | G14: 75000 | H14: =E14*G14 | I14: R1 | J14: F42 | K14: Мебель+техника | L14: —
A15: 11 | B15: Матрас 1800×2000 средней жёсткости | C15: M09 | D15: Askona / Ormatek | E15: 1 | F15: шт | G15: 40000 | H15: =E15*G15 | I15: R1 | J15: F42 | K15: Мебель+техника | L15: —
A16: 12 | B16: Тумба прикроватная подвесная 450×500 | C16: M08 | D16: мебельный цех (с консолью) | E16: 2 | F16: шт | G16: 9000 | H16: =E16*G16 | I16: R1 | J16: F43, F44 | K16: Мебель+техника | L16: —
A17: 13 | B17: ТВ-консоль подвесная 1600×300 МДФ эмаль, низ +250 | C17: M08 | D17: мебельный цех | E17: 1 | F17: шт | G17: 32000 | H17: =E17*G17 | I17: R1 | J17: F47 | K17: Мебель+техника | L17: —
A18: 14 | B18: Стол рабочий 1400×600, столешница дуб, консоль/подстолье к стене | C18: M08 | D18: мебельный цех / Woodville | E18: 1 | F18: шт | G18: 35000 | H18: =E18*G18 | I18: R1 | J18: F49 | K18: Мебель+техника | L18: —
A19: 15 | B19: Кресло рабочее эргономичное | C19: — | D19: Chairman / Бюрократ (средний) | E19: 1 | F19: шт | G19: 18000 | H19: =E19*G19 | I19: R1 | J19: F50 | K19: Мебель+техника | L19: —
A20: 16 | B20: Шкаф детский 1800×600×2400, 2 секции, распашной, крепление к стене | C20: M11 | D20: местный цех / Ellipsefurniture | E20: 1 | F20: шт | G20: 38000 | H20: =E20*G20 | I20: R2 | J20: F52 | K20: Мебель+техника | L20: —
A21: 17 | B21: Кровать детская 900×2000 с ящиками для игрушек | C21: M11 | D21: Ellipsefurniture / местный цех | E21: 1 | F21: шт | G21: 28000 | H21: =E21*G21 | I21: R2 | J21: F53 | K21: Мебель+техника | L21: —
A22: 18 | B22: Матрас 900×2000 детский | C22: M11 | D22: Askona / Ormatek | E22: 1 | F22: шт | G22: 12000 | H22: =E22*G22 | I22: R2 | J22: F53 | K22: Мебель+техника | L22: —
A23: 19 | B23: Стол «растущий» 1200×600 с регулировкой | C23: M11 | D23: Mealux / Kidfix-класс | E23: 1 | F23: шт | G23: 24000 | H23: =E23*G23 | I23: R2 | J23: F54 | K23: Мебель+техника | L23: —
A24: 20 | B24: Стул «растущий» | C24: M11 | D24: Mealux / Kotokota-класс | E24: 1 | F24: шт | G24: 9000 | H24: =E24*G24 | I24: R2 | J24: F55 | K24: Мебель+техника | L24: —
... A29: 25 | B29: Доставка, подъём (1 этаж) и сборка отдельностоящей мебели | C29: — | D29: поставщики | E29: 1 | F29: усл | G29: 15000 | H29: =E29*G29 | I29: — | J29: АР-07 | K29: Мебель+техника | L29: —
B31: Итого по спецификации | H31: =SUM(H5:H29)
B32: в т.ч. «Ремонт» | H32: =SUMIF(K5:K29,"Ремонт",H5:H29)
B33: в т.ч. «Мебель+техника» | H33: =SUMIF(K5:K29,"Мебель+техника",H5:H29)

Sheet СП-02.2 Кухня и бытовая техника
A1: СП-02.2. Кухня и бытовая техника
A2: Цены — ориентировочные для Санкт-Петербурга на 10.2026 (средний сегмент, розница/подрядчики), не являются офертой и подлежат проверке у поставщиков перед закупкой. Материалы — по диапазонам 02-concept/materials.json (price_ref) с поправкой на рост цен 1-го полугодия 2026 (INFOline: плитка +17 %, электрика +15 %, ЛКМ +10 %, напольные +10,5 %); расценки работ — калибровка по открытым прайсам СПб (поиск 2026-10-08, источники в 05-estimate/estimate.md).
A4: Поз. | B4: Наименование | C4: Артикул / пример | D4: Производитель | E4: Кол-во | F4: Ед. | G4: Цена ориент., ₽ | H4: Сумма, ₽ | I4: Помещение | J4: Ссылка (лист / id) | K4: Бюджет | L4: Этап сметы | M4: Примечание / расчёт кол-ва
A5: 1 | B5: Модуль K-01 Пенал угловой 600 (сухие продукты; ниша встраиваемой СВЧ — опция) | C5: 600×580×2400 | D5: фабрика СПб по эскизу (M12) | E5: 1 | F5: шт | G5: 38000 | H5: =E5*G5 | I5: R3 | J5: F01; kitchen.md | K5: Мебель+техника | L5: —
A6: 2 | B6: Модуль K-02 База 450, 3 ящика (кастрюли); в ней розетка духовки | C6: 450×620×880 | D6: фабрика СПб по эскизу (M12) | E6: 1 | F6: шт | G6: 22000 | H6: =E6*G6 | I6: R3 | J6: F02; kitchen.md | K6: Мебель+техника | L6: —
A7: 3 | B7: Модуль K-03 База 600 под духовой шкаф + индукционная панель | C7: 600×620×880 | D7: фабрика СПб по эскизу (M12) | E7: 1 | F7: шт | G7: 16000 | H7: =E7*G7 | I7: R3 | J7: F03; kitchen.md | K7: Мебель+техника | L7: —
A8: 4 | B8: Модуль K-04 База 600, 3 ящика (приборы, основная рабочая зона) | C8: 600×620×880 | D8: фабрика СПб по эскизу (M12) | E8: 1 | F8: шт | G8: 26000 | H8: =E8*G8 | I8: R3 | J8: F04; kitchen.md | K8: Мебель+техника | L8: —
A9: 5 | B9: Модуль K-05 База 600 под мойку (влагостойкая ЛДСП, поддон) | C9: 600×620×880 | D9: фабрика СПб по эскизу (M12) | E9: 1 | F9: шт | G9: 18000 | H9: =E9*G9 | I9: R3 | J9: F05; kitchen.md | K9: Мебель+техника | L9: —
A10: 6 | B10: Модуль K-07 Пенал 600 под встраиваемый холодильник (ниша 1780–1940) | C10: 600×620×2400 | D10: фабрика СПб по эскизу (M12) | E10: 1 | F10: шт | G10: 38000 | H10: =E10*G10 | I10: R3 | J10: F07; kitchen.md | K10: Мебель+техника | L10: —
A11: 7 | B11: Модуль K-08 Доборная панель 40 у W10 | C11: 40×620×2400 | D11: фабрика СПб по эскизу (M12) | E11: 1 | F11: шт | G11: 4000 | H11: =E11*G11 | I11: R3 | J11: F08; kitchen.md | K11: Мебель+техника | L11: —
A12: 8 | B12: Модуль KW-01 Навесной 450 | C12: 450×350×850 | D12: фабрика СПб по эскизу (M12) | E12: 1 | F12: шт | G12: 12000 | H12: =E12*G12 | I12: R3 | J12: F10; kitchen.md | K12: Мебель+техника | L12: —
A13: 9 | B13: Модуль KW-02 Навесной 600 со встроенной вытяжкой | C13: 600×350×850 | D13: фабрика СПб по эскизу (M12) | E13: 1 | F13: шт | G13: 15000 | H13: =E13*G13 | I13: R3 | J13: F11; kitchen.md | K13: Мебель+техника | L13: —
A14: 10 | B14: Модуль KW-03 Навесной 600 | C14: 600×350×850 | D14: фабрика СПб по эскизу (M12) | E14: 1 | F14: шт | G14: 14000 | H14: =E14*G14 | I14: R3 | J14: F12; kitchen.md | K14: Мебель+техника | L14: —
A15: 11 | B15: Модуль KW-04 Навесной 600 с сушкой над мойкой | C15: 600×350×850 | D15: фабрика СПб по эскизу (M12) | E15: 1 | F15: шт | G15: 15000 | H15: =E15*G15 | I15: R3 | J15: F13; kitchen.md | K15: Мебель+техника | L15: —
A16: 12 | B16: Модуль KW-05 Навесной 600 | C16: 600×350×850 | D16: фабрика СПб по эскизу (M12) | E16: 1 | F16: шт | G16: 14000 | H16: =E16*G16 | I16: R3 | J16: F14; kitchen.md | K16: Мебель+техника | L16: —
... A28: 24 | B28: Монтаж кухни (входит в цену фабрики) и подключение встраиваемой техники | C28: — | D28: фабрика/сервис | E28: 1 | F28: усл | G28: 15000 | H28: =E28*G28 | I28: R3 | J28: kitchen.md п.6 | K28: Мебель+техника | L28: —
B30: Итого по спецификации | H30: =SUM(H5:H28)
B31: в т.ч. «Ремонт» | H31: =SUMIF(K5:K28,"Ремонт",H5:H28)
B32: в т.ч. «Мебель+техника» | H32: =SUMIF(K5:K28,"Мебель+техника",H5:H28)

Sheet СП-03.1 Светильники
A1: СП-03.1. Светильники
A2: Цены — ориентировочные для Санкт-Петербурга на 10.2026 (средний сегмент, розница/подрядчики), не являются офертой и подлежат проверке у поставщиков перед закупкой. Материалы — по диапазонам 02-concept/materials.json (price_ref) с поправкой на рост цен 1-го полугодия 2026 (INFOline: плитка +17 %, электрика +15 %, ЛКМ +10 %, напольные +10,5 %); расценки работ — калибровка по открытым прайсам СПб (поиск 2026-10-08, источники в 05-estimate/estimate.md).
A4: Поз. | B4: Наименование | C4: Артикул / пример | D4: Производитель | E4: Кол-во | F4: Ед. | G4: Цена ориент., ₽ | H4: Сумма, ₽ | I4: Помещение | J4: Ссылка (лист / id) | K4: Бюджет | L4: Этап сметы | M4: Примечание / расчёт кол-ва
A5: 1 | B5: Спот встраиваемый LED 7 Вт, 2700 K, CRI ≥ 90, диммируемый, глубина ≤ 80 — группа L2 | C5: Maytoni DL / Elektrostandard | D5: Maytoni / Elektrostandard | E5: 4 | F5: шт | G5: 2700 | H5: =E5*G5 | I5: R3 | J5: L2-1, L2-2, L2-3, L2-4; ЭО-01 | K5: Ремонт | L5: Э13 | M5: 7 Вт
A6: 2 | B6: Люстра столовой 5–6 рожков LED, латунь сатин/ткань, диммируемая — группа L3 | C6: M34 | D6: Maytoni / Freya / Lussole | E6: 1 | F6: шт | G6: 32000 | H6: =E6*G6 | I6: R3 | J6: L3-1; ЭО-01 | K6: Ремонт | L6: Э13 | M6: 40 Вт
A7: 3 | B7: Бра латунь сатин C8 с абажуром — группа L4 | C7: M34 | D7: Maytoni / Freya / Odeon Light | E7: 2 | F7: шт | G7: 9500 | H7: =E7*G7 | I7: R3 | J7: L4-1, L4-2; ЭО-01 | K7: Ремонт | L7: Э13 | M7: 6 Вт
A8: 4 | B8: Спот встраиваемый LED 7 Вт, 2700 K, CRI ≥ 90, диммируемый, глубина ≤ 80 — группа L6 | C8: Maytoni DL / Elektrostandard | D8: Maytoni / Elektrostandard | E8: 4 | F8: шт | G8: 2700 | H8: =E8*G8 | I8: R7 | J8: L6-1, L6-2, L6-3, L6-4; ЭО-01 | K8: Ремонт | L8: Э13 | M8: 5 Вт
A9: 5 | B9: Люстра спальни, диммируемая, латунь/ткань — группа L8 | C9: M34 | D9: Maytoni / Odeon Light / Freya | E9: 1 | F9: шт | G9: 24000 | H9: =E9*G9 | I9: R1 | J9: L8-1; ЭО-01 | K9: Ремонт | L9: Э13 | M9: 40 Вт
A10: 6 | B10: Бра латунь сатин C8 с абажуром — группа L11 | C10: M34 | D10: Maytoni / Freya / Odeon Light | E10: 2 | F10: шт | G10: 9500 | H10: =E10*G10 | I10: R1 | J10: L11-1, L11-2; F41; ЭО-01 | K10: Ремонт | L10: Э13 | M10: 5 Вт
A11: 7 | B11: Светильник потолочный рассеянный детской, диммируемый — группа L14 | C11: M34 | D11: Maytoni / Odeon Light / Freya | E11: 1 | F11: шт | G11: 14000 | H11: =E11*G11 | I11: R2 | J11: L14-1; ЭО-01 | K11: Ремонт | L11: Э13 | M11: 40 Вт
A12: 8 | B12: Спот встраиваемый LED 7 Вт, 2700 K, CRI ≥ 90, диммируемый, глубина ≤ 80 — группа L15 | C12: Maytoni DL / Elektrostandard | D12: Maytoni / Elektrostandard | E12: 5 | F12: шт | G12: 2700 | H12: =E12*G12 | I12: R4 | J12: L15-1, L15-2, L15-3, L15-4, L15-5; ЭО-01 | K12: Ремонт | L12: Э13 | M12: 6 Вт
A13: 9 | B13: Спот встраиваемый LED 7 Вт, 2700 K, CRI ≥ 90, диммируемый, глубина ≤ 80 — группа L16 | C13: Maytoni DL / Elektrostandard | D13: Maytoni / Elektrostandard | E13: 3 | F13: шт | G13: 2700 | H13: =E13*G13 | I13: R4 | J13: L16-1, L16-2, L16-3; ЭО-01 | K13: Ремонт | L13: Э13 | M13: 6 Вт
A14: 10 | B14: Спот встраиваемый LED IP44, 3000 K, CRI ≥ 90 — группа L19 | C14: Maytoni Zoom IP44-класс | D14: Maytoni / Elektrostandard | E14: 2 | F14: шт | G14: 3600 | H14: =E14*G14 | I14: R5 | J14: L19-1, L19-2; ЭО-01 | K14: Ремонт | L14: Э13 | M14: 6 Вт
A15: 11 | B15: Спот встраиваемый LED IP65 (над ванной/душем), 3000 K — группа L19 | C15: Maytoni Hoop IP65-класс | D15: Maytoni / Elektrostandard | E15: 2 | F15: шт | G15: 4300 | H15: =E15*G15 | I15: R5 | J15: L19-3, L19-4; ЭО-01 | K15: Ремонт | L15: Э13 | M15: 6 Вт
A16: 12 | B16: LED зеркального шкафа (в составе F72) — группа L20 | C16: в комплекте F72 | D16: — | E16: 1 | F16: шт | G16: 0 | H16: =E16*G16 | I16: R5 | J16: L20-1; F72; ЭО-01 | K16: Ремонт | L16: Э13 | M16: 15 Вт
... A18: 14 | B18: Лента LED 24 В 2700 K CRI ≥ 90 — подсветка рабочей зоны под KW-01..05 | C18: Arlight / Elektrostandard | D18: Arlight | E18: 3.5 | F18: м | G18: 1300 | H18: =E18*G18 | I18: R3 | J18: L1-1; F10; F23; ЭО-01 | K18: Ремонт | L18: Э13 | M18: длина 2.85 м по pos→end + 10 %
A19: 15 | B19: Профиль алюминиевый с рассеивателем для L1-1 | C19: Arlight / Elektrostandard | D19: Arlight | E19: 3 | F19: м | G19: 900 | H19: =E19*G19 | I19: R3 | J19: L1-1 | K19: Ремонт | L19: Э13
A20: 16 | B20: Блок питания 24 В 100 Вт для L1-1 | C20: Arlight ARPV / Mean Well | D20: Arlight / Mean Well | E20: 1 | F20: шт | G20: 3000 | H20: =E20*G20 | I20: R3 | J20: L1-1 | K20: Ремонт | L20: Э13 | M20: 60 Вт × 1,25
A21: 17 | B21: Лента LED 24 В 2700 K CRI ≥ 90 — LED остеклённого яруса буфета F24 | C21: Arlight / Elektrostandard | D21: Arlight | E21: 1 | F21: м | G21: 1300 | H21: =E21*G21 | I21: R3 | J21: L4-3; F24; ЭО-01 | K21: Ремонт | L21: Э13 | M21: длина 0.73 м по pos→end + 10 %
A22: 18 | B22: Профиль алюминиевый с рассеивателем для L4-3 | C22: Arlight / Elektrostandard | D22: Arlight | E22: 1 | F22: м | G22: 900 | H22: =E22*G22 | I22: R3 | J22: L4-3 | K22: Ремонт | L22: Э13
A23: 19 | B23: Блок питания 24 В 30 Вт для L4-3 | C23: Arlight ARPV / Mean Well | D23: Arlight / Mean Well | E23: 1 | F23: шт | G23: 1500 | H23: =E23*G23 | I23: R3 | J23: L4-3 | K23: Ремонт | L23: Э13 | M23: 10 Вт × 1,25
A24: 20 | B24: Лента LED 24 В 2700 K CRI ≥ 90 — подсветка цоколя кухни 2700K | C24: Arlight / Elektrostandard | D24: Arlight | E24: 3.5 | F24: м | G24: 1300 | H24: =E24*G24 | I24: R3 | J24: L5-1; ЭО-01 | K24: Ремонт | L24: Э13 | M24: длина 2.85 м по pos→end + 10 %
A25: 21 | B25: Профиль алюминиевый с рассеивателем для L5-1 | C25: Arlight / Elektrostandard | D25: Arlight | E25: 3 | F25: м | G25: 900 | H25: =E25*G25 | I25: R3 | J25: L5-1 | K25: Ремонт | L25: Э13
A26: 22 | B26: Блок питания 24 В 30 Вт для L5-1 | C26: Arlight ARPV / Mean Well | D26: Arlight / Mean Well | E26: 1 | F26: шт | G26: 1500 | H26: =E26*G26 | I26: R3 | J26: L5-1 | K26: Ремонт | L26: Э13 | M26: 15 Вт × 1,25
A27: 23 | B27: Лента LED 24 В 2700 K CRI ≥ 90 — подсветка цоколя П-дивана 24 В 2700K | C27: Arlight / Elektrostandard | D27: Arlight | E27: 2 | F27: м | G27: 1300 | H27: =E27*G27 | I27: R7 | J27: L7-1; F33; F35; ЭО-01 | K27: Ремонт | L27: Э13 | M27: длина 1.62 м по pos→end + 10 %
A28: 24 | B28: Профиль алюминиевый с рассеивателем для L7-1 | C28: Arlight / Elektrostandard | D28: Arlight | E28: 2 | F28: м | G28: 900 | H28: =E28*G28 | I28: R7 | J28: L7-1 | K28: Ремонт | L28: Э13
A29: 25 | B29: Блок питания 24 В 30 Вт для L7-1 | C29: Arlight ARPV / Mean Well | D29: Arlight / Mean Well | E29: 1 | F29: шт | G29: 1500 | H29: =E29*G29 | I29: R7 | J29: L7-1 | K29: Ремонт | L29: Э13 | M29: 20 Вт × 1,25
A30: 26 | B30: Лента LED 24 В 2700 K CRI ≥ 90 — LED 2700K в теневом пазу карниза буазери F41; БП 24 В в съём | C30: Arlight / Elektrostandard | D30: Arlight | E30: 3.5 | F30: м | G30: 1300 | H30: =E30*G30 | I30: R1 | J30: L9-1; F41; ЭО-01 | K30: Ремонт | L30: Э13 | M30: длина 2.9 м по pos→end + 10 %
A31: 27 | B31: Профиль алюминиевый с рассеивателем для L9-1 | C31: Arlight / Elektrostandard | D31: Arlight | E31: 3 | F31: м | G31: 900 | H31: =E31*G31 | I31: R1 | J31: L9-1 | K31: Ремонт | L31: Э13
A32: 28 | B32: Блок питания 24 В 60 Вт для L9-1 | C32: Arlight ARPV / Mean Well | D32: Arlight / Mean Well | E32: 1 | F32: шт | G32: 2200 | H32: =E32*G32 | I32: R1 | J32: L9-1 | K32: Ремонт | L32: Э13 | M32: 30 Вт × 1,25
A33: 29 | B33: Лента LED 24 В 2700 K CRI ≥ 90 — LED 2700K в карнизе по кромке ниши шторы CN-1 | C33: Arlight / Elektrostandard | D33: Arlight | E33: 4 | F33: м | G33: 1300 | H33: =E33*G33 | I33: R1 | J33: L10-1; ЭО-01 | K33: Ремонт | L33: Э13 | M33: длина 3.38 м по pos→end + 10 %
A34: 30 | B34: Профиль алюминиевый с рассеивателем для L10-1 | C34: Arlight / Elektrostandard | D34: Arlight | E34: 4 | F34: м | G34: 900 | H34: =E34*G34 | I34: R1 | J34: L10-1 | K34: Ремонт | L34: Э13
A35: 31 | B35: Блок питания 24 В 100 Вт для L10-1 | C35: Arlight ARPV / Mean Well | D35: Arlight / Mean Well | E35: 1 | F35: шт | G35: 3000 | H35: =E35*G35 | I35: R1 | J35: L10-1 | K35: Ремонт | L35: Э13 | M35: 55 Вт × 1,25
A36: 32 | B36: Лента LED 24 В 2700 K CRI ≥ 90 — подсветка снизу ТВ-консоли F47 2700K | C36: Arlight / Elektrostandard | D36: Arlight | E36: 2 | F36: м | G36: 1300 | H36: =E36*G36 | I36: R1 | J36: L12-1; F47; ЭО-01 | K36: Ремонт | L36: Э13 | M36: длина 1.6 м по pos→end + 10 %
A37: 33 | B37: Профиль алюминиевый с рассеивателем для L12-1 | C37: Arlight / Elektrostandard | D37: Arlight | E37: 2 | F37: м | G37: 900 | H37: =E37*G37 | I37: R1 | J37: L12-1 | K37: Ремонт | L37: Э13
A38: 34 | B38: Блок питания 24 В 30 Вт для L12-1 | C38: Arlight ARPV / Mean Well | D38: Arlight / Mean Well | E38: 1 | F38: шт | G38: 1500 | H38: =E38*G38 | I38: R1 | J38: L12-1 | K38: Ремонт | L38: Э13 | M38: 10 Вт × 1,25
A39: 35 | B39: Лента LED 24 В 2700 K CRI ≥ 90 — подсветка шкафа-купе F45 по датчикам открытия; БП на антресо | C39: Arlight / Elektrostandard | D39: Arlight | E39: 2.5 | F39: м | G39: 1300 | H39: =E39*G39 | I39: R1 | J39: L13-1; F45; ЭО-01 | K39: Ремонт | L39: Э13 | M39: длина 1.88 м по pos→end + 10 %
A40: 36 | B40: Профиль алюминиевый с рассеивателем для L13-1 | C40: Arlight / Elektrostandard | D40: Arlight | E40: 2 | F40: м | G40: 900 | H40: =E40*G40 | I40: R1 | J40: L13-1 | K40: Ремонт | L40: Э13
A41: 37 | B41: Блок питания 24 В 30 Вт для L13-1 | C41: Arlight ARPV / Mean Well | D41: Arlight / Mean Well | E41: 1 | F41: шт | G41: 1500 | H41: =E41*G41 | I41: R1 | J41: L13-1 | K41: Ремонт | L41: Э13 | M41: 20 Вт × 1,25
A42: 38 | B42: Лента LED 24 В 2700 K CRI ≥ 90 — ночная подсветка в плинтусе коридора/прихожей по датчикам дв | C42: Arlight / Elektrostandard | D42: Arlight | E42: 2.5 | F42: м | G42: 1300 | H42: =E42*G42 | I42: R4 | J42: L17-1; ЭО-01 | K42: Ремонт | L42: Э13 | M42: длина 2.25 м по pos→end + 10 %
...

Sheet СП-03.2 Электроустановочные изд
A1: СП-03.2. Электроустановочные изделия (серия)
A2: Цены — ориентировочные для Санкт-Петербурга на 10.2026 (средний сегмент, розница/подрядчики), не являются офертой и подлежат проверке у поставщиков перед закупкой. Материалы — по диапазонам 02-concept/materials.json (price_ref) с поправкой на рост цен 1-го полугодия 2026 (INFOline: плитка +17 %, электрика +15 %, ЛКМ +10 %, напольные +10,5 %); расценки работ — калибровка по открытым прайсам СПб (поиск 2026-10-08, источники в 05-estimate/estimate.md).
A4: Поз. | B4: Наименование | C4: Артикул / пример | D4: Производитель | E4: Кол-во | F4: Ед. | G4: Цена ориент., ₽ | H4: Сумма, ₽ | I4: Помещение | J4: Ссылка (лист / id) | K4: Бюджет | L4: Этап сметы | M4: Примечание / расчёт кол-ва
A5: 1 | B5: Розетка 2П+З 16 А со шторками (механизм) | C5: серия ArtGallery, «молочный» | D5: Systeme Electric | E5: 36 | F5: шт | G5: 480 | H5: =E5*G5 | I5: все | J5: P-K01, P-K02, P-K05, P-K06, P-K07, P-K08, P-K09, P-K10, P-K13, P-K14, P-K15, P-K16, P-B01, P-B04a, P-R03, P-R04, P-R05, P-R06, P-R07, P-R08, P-C01, P-C02, P-C04, P-C05, P-H01, P-H02, P-H03 | K5: Ремонт | L5: Э13
A6: 2 | B6: Вывод кабеля (механизм-заглушка с выводом) / клеммная колодка (механизм) | C6: серия ArtGallery, «молочный» | D6: Systeme Electric | E6: 25 | F6: шт | G6: 400 | H6: =E6*G6 | I6: все | J6: P-K03, P-K10a, P-K11, P-K12, P-B02, P-B03, P-B04, P-B05, P-B06, P-B07, P-B08, P-R10, P-R11, P-R12, P-R13, P-R14, P-R15, P-H04, P-H05, P-V03, P-V04, P-V05, P-V06, P-L04, P-L05 | K6: Ремонт | L6: Э13
A7: 3 | B7: Розетка 2П+З 16 А IP44 с крышкой (механизм) | C7: серия ArtGallery, «молочный» | D7: Systeme Electric | E7: 6 | F7: шт | G7: 950 | H7: =E7*G7 | I7: все | J7: P-K04, P-V01, P-V02, P-L01, P-L02, P-L03 | K7: Ремонт | L7: Э13
A8: 4 | B8: Розетка 2П+З + USB A/C (быстрая зарядка) (механизм) | C8: серия ArtGallery, «молочный» | D8: Systeme Electric | E8: 5 | F8: шт | G8: 2300 | H8: =E8*G8 | I8: все | J8: P-B03a, P-B04b, P-R01, P-R02, P-C03 | K8: Ремонт | L8: Э13
A9: 5 | B9: Выключатель кнопочный 1кл (под Zigbee-диммер) (механизм) | C9: серия ArtGallery, «молочный» | D9: Systeme Electric | E9: 2 | F9: шт | G9: 700 | H9: =E9*G9 | I9: все | J9: S1, S11 | K9: Ремонт | L9: Э13
A10: 6 | B10: Выключатель 2-клавишный (механизм) | C10: серия ArtGallery, «молочный» | D10: Systeme Electric | E10: 4 | F10: шт | G10: 650 | H10: =E10*G10 | I10: все | J10: S2, S3, S4, S12 | K10: Ремонт | L10: Э13
A11: 7 | B11: Переключатель проходной 2-клавишный (механизм) | C11: серия ArtGallery, «молочный» | D11: Systeme Electric | E11: 1 | F11: шт | G11: 850 | H11: =E11*G11 | I11: все | J11: S5 | K11: Ремонт | L11: Э13
A12: 8 | B12: Переключатель перекрёстный (механизм) | C12: серия ArtGallery, «молочный» | D12: Systeme Electric | E12: 1 | F12: шт | G12: 800 | H12: =E12*G12 | I12: все | J12: S6 | K12: Ремонт | L12: Э13
A13: 9 | B13: Переключатель проходной (механизм) | C13: серия ArtGallery, «молочный» | D13: Systeme Electric | E13: 3 | F13: шт | G13: 600 | H13: =E13*G13 | I13: все | J13: S7, S8, S13 | K13: Ремонт | L13: Э13
A14: 10 | B14: Выключатель 1-клавишный (механизм) | C14: серия ArtGallery, «молочный» | D14: Systeme Electric | E14: 4 | F14: шт | G14: 450 | H14: =E14*G14 | I14: все | J14: S9, S10, S14, S15 | K14: Ремонт | L14: Э13
A15: 11 | B15: Рамка 1-постовая | C15: ArtGallery, «молочный» | D15: Systeme Electric | E15: 69 | F15: шт | G15: 320 | H15: =E15*G15 | I15: все | J15: sockets (1 пост) + switches | K15: Ремонт | L15: Э13 | M15: комбинирование в многопостовые рамки — по ЭО-02/ЭМ-01 при комплектации
A16: 12 | B16: Рамка 2-постовая | C16: ArtGallery, «молочный» | D16: Systeme Electric | E16: 9 | F16: шт | G16: 520 | H16: =E16*G16 | I16: все | J16: sockets «2P+PE×2» | K16: Ремонт | L16: Э13
A17: 13 | B17: Модуль Zigbee диммер/реле за клавишей или контроллер LED 24 В Zigbee (работает без шлюза) | C17: Aqara / Sonoff / Gledopto | D17: Aqara / Sonoff | E17: 8 | F17: шт | G17: 3500 | H17: =E17*G17 | I17: R2, R3, R7 | J17: light_groups L1, L2, L3, L4, L5, L6, L7, L14; electrical.accepted.lighting_control | K17: Ремонт | L17: Э13
A18: 14 | B18: Подрозетник (кирпич/ГКЛ), с шаблоном | C18: Hegel / Schneider | D18: Hegel | E18: 87 | F18: шт | G18: 90 | H18: =E18*G18 | I18: все | J18: посты sockets + switches | K18: Ремонт | L18: Э04
B20: Итого по спецификации | H20: =SUM(H5:H18)
B21: в т.ч. «Ремонт» | H21: =SUMIF(K5:K18,"Ремонт",H5:H18)
B22: в т.ч. «Мебель+техника» | H22: =SUMIF(K5:K18,"Мебель+техника",H5:H18)

Sheet СП-03.3 Щит ЭМ-03 и кабельная п
A1: СП-03.3. Щит ЭМ-03 и кабельная продукция
A2: Цены — ориентировочные для Санкт-Петербурга на 10.2026 (средний сегмент, розница/подрядчики), не являются офертой и подлежат проверке у поставщиков перед закупкой. Материалы — по диапазонам 02-concept/materials.json (price_ref) с поправкой на рост цен 1-го полугодия 2026 (INFOline: плитка +17 %, электрика +15 %, ЛКМ +10 %, напольные +10,5 %); расценки работ — калибровка по открытым прайсам СПб (поиск 2026-10-08, источники в 05-estimate/estimate.md).
A4: Поз. | B4: Наименование | C4: Артикул / пример | D4: Производитель | E4: Кол-во | F4: Ед. | G4: Цена ориент., ₽ | H4: Сумма, ₽ | I4: Помещение | J4: Ссылка (лист / id) | K4: Бюджет | L4: Этап сметы | M4: Примечание / расчёт кол-ва
A5: 1 | B5: Щит ЩРН-48 (4×12 модулей) накладной/полувстраиваемый IP31 | C5: Hager Volta / Schneider Mini Pragma | D5: Hager / Schneider | E5: 1 | F5: шт | G5: 7500 | H5: =E5*G5 | I5: R4 | J5: U15; panel.json panel; ЭМ-03 | K5: Ремонт | L5: Э04 | M5: занято 32 из 48 мод.
A6: 2 | B6: Автомат вводной 2P C63 6 кА | C6: вводной автомат 2P C63, 6 кА (при выделенной 10–11 кВт — C50 | D6: Schneider Easy9 / Hager / IEK Armat | E6: 1 | F6: шт | G6: 2600 | H6: =E6*G6 | I6: R4 | J6: QS0/QF0; panel.json input | K6: Ремонт | L6: Э04
A7: 3 | B7: УЗИП тип 2 (1P+N) 20 кА + защита | C7: УЗИП тип 2 (1P+N) 20 кА + автомат/вставка по паспорту | D7: Schneider Easy9 / Hager / IEK Armat | E7: 1 | F7: шт | G7: 6500 | H7: =E7*G7 | I7: R4 | J7: FV1; panel.json input | K7: Ремонт | L7: Э04
A8: 4 | B8: Реле контроля напряжения 63 А | C8: реле контроля напряжения 63 А (УЗМ-51М/RBUZ D63t), 170–260 В | D8: Schneider Easy9 / Hager / IEK Armat | E8: 1 | F8: шт | G8: 4500 | H8: =E8*G8 | I8: R4 | J8: KV1; panel.json input | K8: Ремонт | L8: Э04
A9: 5 | B9: УЗО 2P 80 А 100 мА тип S (противопожарное) | C9: УЗО 2P 80 А 100 мА тип S (противопожарное, селективное к гру | D9: Schneider Easy9 / Hager / IEK Armat | E9: 1 | F9: шт | G9: 9500 | H9: =E9*G9 | I9: R4 | J9: QD0; panel.json input | K9: Ремонт | L9: Э04
A10: 6 | B10: Индикатор наличия напряжения | C10: индикатор наличия напряжения | D10: Schneider Easy9 / Hager / IEK Armat | E10: 1 | F10: шт | G10: 600 | H10: =E10*G10 | I10: R4 | J10: HL; panel.json input | K10: Ремонт | L10: Э04
A11: 7 | B11: Автомат 1P C10 6 кА | C11: Schneider Easy9 / Hager / IEK Armat | D11: Schneider / Hager | E11: 2 | F11: шт | G11: 650 | H11: =E11*G11 | I11: R4 | J11: C1, C2; ЭМ-03 | K11: Ремонт | L11: Э04
A12: 8 | B12: АВДТ 1P+N C10 30 мА тип A 6 кА | C12: Schneider Easy9 / Hager / IEK Armat | D12: Schneider / Hager | E12: 1 | F12: шт | G12: 3000 | H12: =E12*G12 | I12: R4 | J12: C3; ЭМ-03 | K12: Ремонт | L12: Э04
A13: 9 | B13: АВДТ 1P+N C16 30 мА тип A 6 кА | C13: Schneider Easy9 / Hager / IEK Armat | D13: Schneider / Hager | E13: 17 | F13: шт | G13: 3000 | H13: =E13*G13 | I13: R4 | J13: C4, C5, C6, C8, C9, C10, C11, C13, C14, C15, C16, C17, C18, C19, C20, C21, C22; ЭМ-03 | K13: Ремонт | L13: Э04
A14: 10 | B14: АВДТ 1P+N C32 30 мА тип A 6 кА (2 мод.) | C14: Schneider Easy9 / Hager / IEK Armat | D14: Schneider / Hager | E14: 1 | F14: шт | G14: 5200 | H14: =E14*G14 | I14: R4 | J14: C7; ЭМ-03 | K14: Ремонт | L14: Э04
A15: 11 | B15: АВДТ 1P+N C16 10 мА тип A 6 кА | C15: Schneider Easy9 / Hager / IEK Armat | D15: Schneider / Hager | E15: 1 | F15: шт | G15: 4800 | H15: =E15*G15 | I15: R4 | J15: C12; ЭМ-03 | K15: Ремонт | L15: Э04
A16: 12 | B16: Шины N/PE, гребёнки, заглушки, маркировка, DIN-розетки ×3 (P-SS1 в U16) | C16: — | D16: Hager / Schneider | E16: 1 | F16: компл | G16: 6500 | H16: =E16*G16 | I16: R4 | J16: panel.json; P-SS1 | K16: Ремонт | L16: Э04
A17: 13 | B17: Кабель ВВГнг(А)-LS 3×1,5 | C17: ГОСТ 31996 | D17: Кольчугино / Конкорд / Севкабель | E17: =CEILING(240.6*1.15,5) | F17: м | G17: 115 | H17: =E17*G17 | I17: все | J17: C1, C2, C3; panel.json length_m | K17: Ремонт | L17: Э04 | M17: Σ 240.6 м × 1,15
A18: 14 | B18: Кабель ВВГнг(А)-LS 3×2,5 | C18: ГОСТ 31996 | D18: Кольчугино / Конкорд / Севкабель | E18: =CEILING(338.8*1.15,5) | F18: м | G18: 170 | H18: =E18*G18 | I18: все | J18: C4, C5, C6, C8, C9, C10, C11, C12, C13, C14, C15, C16, C17, C18, C19, C20, C21, C22; panel.json length_m | K18: Ремонт | L18: Э04 | M18: Σ 338.8 м × 1,15
A19: 15 | B19: Кабель ВВГнг(А)-LS 3×6 | C19: ГОСТ 31996 | D19: Кольчугино / Конкорд / Севкабель | E19: =CEILING(13.2*1.15,5) | F19: м | G19: 430 | H19: =E19*G19 | I19: все | J19: C7; panel.json length_m | K19: Ремонт | L19: Э04 | M19: Σ 13.2 м × 1,15
A20: 16 | B20: Труба гофрированная ПВХ нг Ø20 с зондом (по потолку, D15) | C20: DKC / Ruvinil | D20: DKC | E20: 700 | F20: м | G20: 28 | H20: =E20*G20 | I20: все | J20: panel.json Σ length_m × 1,15 | K20: Ремонт | L20: Э04
A21: 17 | B21: Провод ПуГВ 1×4 + коробки КУП (ДУП ванной и постирочной) | C21: — | D21: — | E21: 2 | F21: компл | G21: 1800 | H21: =E21*G21 | I21: R5, R6 | J21: panel.json rcd_policy (ДУП) | K21: Ремонт | L21: Э04
A22: 18 | B22: Крепёж кабеля: клипсы, дюбель-хомуты, распаечные коробки (доступные), клеммы Wago | C22: — | D22: DKC / Wago | E22: 1 | F22: компл | G22: 9000 | H22: =E22*G22 | I22: все | J22: 23 групп | K22: Ремонт | L22: Э04
B24: Итого по спецификации | H24: =SUM(H5:H22)
B25: в т.ч. «Ремонт» | H25: =SUMIF(K5:K22,"Ремонт",H5:H22)
B26: в т.ч. «Мебель+техника» | H26: =SUMIF(K5:K22,"Мебель+техника",H5:H22)

Sheet СП-04 Сантехника, мебель ванной
A1: СП-04. Сантехника, мебель ванной и ВК-материалы
A2: Цены — ориентировочные для Санкт-Петербурга на 10.2026 (средний сегмент, розница/подрядчики), не являются офертой и подлежат проверке у поставщиков перед закупкой. Материалы — по диапазонам 02-concept/materials.json (price_ref) с поправкой на рост цен 1-го полугодия 2026 (INFOline: плитка +17 %, электрика +15 %, ЛКМ +10 %, напольные +10,5 %); расценки работ — калибровка по открытым прайсам СПб (поиск 2026-10-08, источники в 05-estimate/estimate.md).
A4: Поз. | B4: Наименование | C4: Артикул / пример | D4: Производитель | E4: Кол-во | F4: Ед. | G4: Цена ориент., ₽ | H4: Сумма, ₽ | I4: Помещение | J4: Ссылка (лист / id) | K4: Бюджет | L4: Этап сметы | M4: Примечание / расчёт кол-ва
A5: 1 | B5: Ванна 1700×750 акрил усиленный/кварил, ножки, экран — облицовка плиткой с ревизией H6 | C5: Riho / Ravak / Am.Pm | D5: Riho / Ravak | E5: 1 | F5: шт | G5: 42000 | H5: =E5*G5 | I5: R5 | J5: F66; P03; M24 | K5: Ремонт | L5: Э13
A6: 2 | B6: Сифон-автомат ванны с переливом (выпуск у правого торца) | C6: Viega Simplex / Alcaplast | D6: Viega / Alcaplast | E6: 1 | F6: шт | G6: 6500 | H6: =E6*G6 | I6: R5 | J6: P03; S2 | K6: Ремонт | L6: Э13
A7: 3 | B7: Смеситель для ванны настенный, латунь браш C8 | C7: WasserKRAFT / Lemark | D7: WasserKRAFT | E7: 1 | F7: шт | G7: 18000 | H7: =E7*G7 | I7: R5 | J7: P03; WB4 | K7: Ремонт | L7: Э13
A8: 4 | B8: Термостат скрытого монтажа на 2 потребителя (встраиваемая часть + лицевая панель), латунь браш | C8: WasserKRAFT / Lemark / Grohe | D8: WasserKRAFT | E8: 1 | F8: компл | G8: 38000 | H8: =E8*G8 | I8: R5 | J8: P04; WB3; D23 | K8: Ремонт | L8: Э05
A9: 5 | B9: Верхний душ 250 + кронштейн, ручной душ со шлангом и подключением, латунь браш | C9: WasserKRAFT / Lemark | D9: WasserKRAFT | E9: 1 | F9: компл | G9: 20000 | H9: =E9*G9 | I9: R5 | J9: P04 | K9: Ремонт | L9: Э13
A10: 6 | B10: Трап линейный низкий 800, h ≤ 70, под плитку, с гидрозатвором и фланцем ГИ | C10: Pestan Confluo / Alcaplast Low | D10: Pestan / Alcaplast | E10: 1 | F10: шт | G10: 16000 | H10: =E10*G10 | I10: R5 | J10: F67; P04; S1; узел 7; D18 | K10: Ремонт | L10: Э05
A11: 7 | B11: Стекло душа фиксированное 315×2000, 8 мм, профиль на клею, стабилизатор к потолку (латунь) | C11: по замеру | D11: стекольная мастерская СПб | E11: 1 | F11: компл | G11: 22000 | H11: =E11*G11 | I11: R5 | J11: F68 | K11: Ремонт | L11: Э13
A12: 8 | B12: Инсталляция для подвесного унитаза (рама к стене, D3) | C12: Geberit Duofix / Grohe Rapid SL | D12: Geberit | E12: 1 | F12: шт | G12: 28000 | H12: =E12*G12 | I12: R5 | J12: F69; P01 | K12: Ремонт | L12: Э05
A13: 9 | B13: Кнопка смыва, латунь браш | C13: Geberit Sigma / Grohe | D13: Geberit | E13: 1 | F13: шт | G13: 7000 | H13: =E13*G13 | I13: R5 | J13: F69; P01 | K13: Ремонт | L13: Э13
A14: 10 | B14: Унитаз подвесной безободковый + сиденье микролифт | C14: Jacob Delafon / Laufen Pro | D14: Laufen / Jacob Delafon | E14: 1 | F14: шт | G14: 28000 | H14: =E14*G14 | I14: R5 | J14: F70; P01 | K14: Ремонт | L14: Э13
A15: 11 | B15: Тумба подвесная 900×480, 2 ящика, шалфей C4, столешница 12 мм + раковина | C15: Aqwella / Opadiris | D15: Aqwella / Opadiris | E15: 1 | F15: компл | G15: 42000 | H15: =E15*G15 | I15: R5 | J15: F71; P02; M23 | K15: Ремонт | L15: Э13
A16: 12 | B16: Зеркальный шкаф 900×750×150 с LED и розеткой | C16: Aqwella / Opadiris | D16: Aqwella | E16: 1 | F16: шт | G16: 24000 | H16: =E16*G16 | I16: R5 | J16: F72; L20; M23 | K16: Ремонт | L16: Э13
... A20: 16 | B20: Полотенцесушитель электрический 400×800, класс II IP44, латунь/бронза | C20: Сунержа / Terminus | D20: Сунержа | E20: 1 | F20: шт | G20: 24000 | H20: =E20*G20 | I20: R5 | J20: F75; P05; P-V03 | K20: Ремонт | L20: Э13
A21: 17 | B21: Мойка кухни кварцевая 1 чаша 500×450 + сифон с переливом | C21: Granfest / Florentina | D21: Granfest | E21: 1 | F21: шт | G21: 14000 | H21: =E21*G21 | I21: R3 | J21: F19; P06 | K21: Ремонт | L21: Э13 | M21: №34: сантехника — бюджет «Ремонт»
A22: 18 | B22: Смеситель кухни с краном питьевой воды, латунь браш | C22: Lemark / WasserKRAFT | D22: Lemark | E22: 1 | F22: шт | G22: 15000 | H22: =E22*G22 | I22: R3 | J22: F19; P06 | K22: Ремонт | L22: Э13
A23: 19 | B23: Фильтр питьевой 3-ступенчатый под мойкой (без накопителя) | C23: Аквафор Кристалл / Гейзер | D23: Аквафор | E23: 1 | F23: шт | G23: 8500 | H23: =E23*G23 | I23: R3 | J23: F20; P08 | K23: Ремонт | L23: Э13
A24: 20 | B24: Хозмойка накладная 450 + смеситель + сифон с отводом СМА | C24: керамика/нерж. | D24: Granfest / Lemark | E24: 1 | F24: компл | G24: 16000 | H24: =E24*G24 | I24: R6 | J24: F78; P09; S6 | K24: Ремонт | L24: Э13
A25: 21 | B25: Кран шаровой ¾″ для СМА + сифон/отвод слива СМА и конденсата СМ | C25: Valtec / Itap | D25: Valtec | E25: 1 | F25: компл | G25: 2500 | H25: =E25*G25 | I25: R6 | J25: P10, P11; WL2; S7 | K25: Ремонт | L25: Э05
A26: 22 | B26: Кран шаровой квартирный ½″–¾″ (ХВС, ГВС) | C26: Itap Ideal / Valtec Base | D26: Itap | E26: 4 | F26: шт | G26: 1200 | H26: =E26*G26 | I26: R5, R6 | J26: N1, N2 chain | K26: Ремонт | L26: Э05
A27: 23 | B27: Фильтр-редуктор комбинированный 100 мкм с манометром, 3,0 бар | C27: Honeywell FK06-класс / Valtec | D27: Valtec / Honeywell | E27: 4 | F27: шт | G27: 5500 | H27: =E27*G27 | I27: R5, R6 | J27: N1, N2 chain; summary.filter | K27: Ремонт | L27: Э05
A28: 24 | B28: Обратный клапан ½″–¾″ | C28: Valtec | D28: Valtec | E28: 4 | F28: шт | G28: 700 | H28: =E28*G28 | I28: R5, R6 | J28: N1, N2 chain | K28: Ремонт | L28: Э05
A29: 25 | B29: Счётчик ИПУ Ду15 с импульсным выходом (если не установлены застройщиком) | C29: Пульс / Декаст | D29: Пульс | E29: 4 | F29: шт | G29: 2300 | H29: =E29*G29 | I29: R5, R6 | J29: N1, N2 chain | K29: Ремонт | L29: Э05 | M29: [ДОПУЩЕНИЕ] уточнить наличие у застройщика
A30: 26 | B30: Коллектор ¾″ (гребёнка) ХВС/ГВС — корпус | C30: Valtec VTc.580 | D30: Valtec | E30: 4 | F30: шт | G30: 2400 | H30: =E30*G30 | I30: R5, R6 | J30: N1, N2 chain (коллекторы) | K30: Ремонт | L30: Э05
A31: 27 | B31: Выход коллектора с шаровым краном ½″ / евроконус | C31: Valtec | D31: Valtec | E31: 13 | F31: шт | G31: 750 | H31: =E31*G31 | I31: R5, R6 | J31: N1, N2: выходы ХВС/ГВС | K31: Ремонт | L31: Э05
A32: 28 | B32: Труба PEX-a 16×2,2 (цельные отрезки, без соединений в подиуме/облицовке) | C32: Rehau Rautitan / Valtec PEX-a | D32: Rehau | E32: 21 | F32: м | G32: 190 | H32: =E32*G32 | I32: R3, R5, R6 | J32: plumbing.json pipes.water WB1–WB4, WK1, WL1, WL2 | K32: Ремонт | L32: Э05 | M32: Σ трасс × линии = 18.26 м × 1,15
A33: 29 | B33: Теплоизоляция 9 мм (ГВС) / 6 мм антиконденсатная (ХВС) | C33: Energoflex / K-Flex | D33: Energoflex | E33: 21 | F33: м | G33: 60 | H33: =E33*G33 | I33: R3, R5, R6 | J33: pipes.water_material | K33: Ремонт | L33: Э05
A34: 30 | B34: Водорозетка латунная ½″ (выводы к приборам) | C34: Rehau / Valtec | D34: Valtec | E34: 12 | F34: шт | G34: 900 | H34: =E34*G34 | I34: R3, R5, R6 | J34: pipes.water: выводы | K34: Ремонт | L34: Э05
A35: 31 | B35: Фитинги на надвижной гильзе (уголки, тройники, переходники), ≈ 3 на вывод | C35: Rehau Everloc | D35: Rehau | E35: 36 | F35: шт | G35: 450 | H35: =E35*G35 | I35: R3, R5, R6 | J35: pipes.water | K35: Ремонт | L35: Э05
A36: 32 | B36: Труба ПП канализационная Ø50 (малошумная в коробах) | C36: Ostendorf / Sinikon | D36: Ostendorf | E36: 8.5 | F36: м | G36: 260 | H36: =E36*G36 | I36: R3, R5, R6 | J36: sewer S1, S2, S4–S7 | K36: Ремонт | L36: Э05 | M36: Σ L = 7.37 м × 1,15
A37: 33 | B37: Труба ПП канализационная Ø110 | C37: Ostendorf / Sinikon | D37: Ostendorf | E37: 1.5 | F37: м | G37: 480 | H37: =E37*G37 | I37: R5 | J37: sewer S3 | K37: Ремонт | L37: Э05 | M37: Σ L = 1.26 м × 1,15
A38: 34 | B38: Фасонные части ПП (отводы 15–45°, тройники, эксц. переходы 110/50), хомуты с резиной | C38: Ostendorf | D38: Ostendorf | E38: 23 | F38: шт | G38: 350 | H38: =E38*G38 | I38: R3, R5, R6 | J38: sewer S1–S7; заглушка P12 | K38: Ремонт | L38: Э05 | M38: ≈ 3 на трассу + 2 перехода
A39: 35 | B39: Заглушка Ø110 с ревизией (выпуск бывшего WC постирочной) | C39: — | D39: Ostendorf | E39: 1 | F39: шт | G39: 900 | H39: =E39*G39 | I39: R6 | J39: P12; D7; planning demolition F1 | K39: Ремонт | L39: Э05
A40: 36 | B40: Люк ревизионный 300×600 — люк-невидимка нажимной под плитку/покраску | C40: Практика / Revizor | D40: Практика | E40: 1 | F40: шт | G40: 9500 | H40: =E40*G40 | I40: R5 | J40: H1; ВК-03 | K40: Ремонт | L40: Э08
A41: 37 | B41: Люк ревизионный 300×400 — люк под плитку с уплотнением (зона орошения), | C41: Практика / Revizor | D41: Практика | E41: 1 | F41: шт | G41: 7500 | H41: =E41*G41 | I41: R5 | J41: H2; ВК-03 | K41: Ремонт | L41: Э08
A42: 38 | B42: Люк ревизионный 300×400 — люк-невидимка над столешницей хозмойки | C42: Практика / Revizor | D42: Практика | E42: 1 | F42: шт | G42: 7500 | H42: =E42*G42 | I42: R6 | J42: H3; ВК-03 | K42: Ремонт | L42: Э08
A43: 39 | B43: Люк ревизионный 300×300 — ревизия в экране (под плитку) | C43: Практика / Revizor | D43: Практика | E43: 1 | F43: шт | G43: 5000 | H43: =E43*G43 | I43: R5 | J43: H6; ВК-03 | K43: Ремонт | L43: Э08
A44: 40 | B44: Монтажный комплект: кронштейны, шумоизоляция, ФУМ, герметики | C44: — | D44: — | E44: 1 | F44: компл | G44: 6000 | H44: =E44*G44 | I44: R3, R5, R6 | J44: ВК-01 | K44: Ремонт | L44: Э05
...

Sheet СП-02.3 Двери и фурнитура
A1: СП-02.3. Двери и фурнитура
A2: Цены — ориентировочные для Санкт-Петербурга на 10.2026 (средний сегмент, розница/подрядчики), не являются офертой и подлежат проверке у поставщиков перед закупкой. Материалы — по диапазонам 02-concept/materials.json (price_ref) с поправкой на рост цен 1-го полугодия 2026 (INFOline: плитка +17 %, электрика +15 %, ЛКМ +10 %, напольные +10,5 %); расценки работ — калибровка по открытым прайсам СПб (поиск 2026-10-08, источники в 05-estimate/estimate.md).
A4: Поз. | B4: Наименование | C4: Артикул / пример | D4: Производитель | E4: Кол-во | F4: Ед. | G4: Цена ориент., ₽ | H4: Сумма, ₽ | I4: Помещение | J4: Ссылка (лист / id) | K4: Бюджет | L4: Этап сметы | M4: Примечание / расчёт кол-ва
A5: 1 | B5: Дверь Д-1 (D1): полотно 800 × 2100 × 40, МДФ эмаль C1 филёнчатое, коробка, наличники 70–80 с цоколем | C5: линии неоклассики под эмаль | D5: Софья / Волховец / ProfilDoors | E5: 1 | F5: компл | G5: 42000 | H5: =E5*G5 | I5: R1 | J5: D1; АР-08; M19 | K5: Ремонт | L5: Э12 | M5: проём 900 × 2180 (O8 1099 → добор ПГП 199 у y 4621..4820; над проёмом — надпроёмная панель до +2750, M19)
A6: 2 | B6: Петли скрытые 3D для Д-1 | C6: AGB Eclipse / Simonswerk Tectus-класс | D6: AGB | E6: 3 | F6: шт | G6: 2600 | H6: =E6*G6 | I6: R1 | J6: D1 | K6: Ремонт | L6: Э12
A7: 3 | B7: Ручка на розетке латунь сатин C8 для Д-1 | C7: Morelli / Fratelli Cattini | D7: Fratelli Cattini | E7: 1 | F7: компл | G7: 3800 | H7: =E7*G7 | I7: R1 | J7: D1 | K7: Ремонт | L7: Э12
A8: 4 | B8: Защёлка магнитная для Д-1 | C8: AGB Polaris | D8: AGB | E8: 1 | F8: шт | G8: 1500 | H8: =E8*G8 | I8: R1 | J8: D1 | K8: Ремонт | L8: Э12
A9: 5 | B9: Ограничитель настенный (не в пол, D3) для Д-1 | C9: Morelli | D9: Morelli | E9: 1 | F9: шт | G9: 1100 | H9: =E9*G9 | I9: R1 | J9: D1 | K9: Ремонт | L9: Э12
A10: 6 | B10: Уплотнитель акустический по коробке для Д-1 | C10: — | D10: — | E10: 1 | F10: компл | G10: 900 | H10: =E10*G10 | I10: R1 | J10: D1 | K10: Ремонт | L10: Э12
A11: 7 | B11: Дверь Д-2 (D2): полотно 800 × 2100 × 40, МДФ эмаль C1 филёнчатое, коробка, наличники 70–80 с цоколем | C11: линии неоклассики под эмаль | D11: Софья / Волховец / ProfilDoors | E11: 1 | F11: компл | G11: 42000 | H11: =E11*G11 | I11: R2 | J11: D2; АР-08; M19 | K11: Ремонт | L11: Э12 | M11: проём 880 × 2180
A12: 8 | B12: Петли скрытые 3D для Д-2 | C12: AGB Eclipse / Simonswerk Tectus-класс | D12: AGB | E12: 3 | F12: шт | G12: 2600 | H12: =E12*G12 | I12: R2 | J12: D2 | K12: Ремонт | L12: Э12
A13: 9 | B13: Ручка на розетке латунь сатин C8 для Д-2 | C13: Morelli / Fratelli Cattini | D13: Fratelli Cattini | E13: 1 | F13: компл | G13: 3800 | H13: =E13*G13 | I13: R2 | J13: D2 | K13: Ремонт | L13: Э12
A14: 10 | B14: Защёлка магнитная для Д-2 | C14: AGB Polaris | D14: AGB | E14: 1 | F14: шт | G14: 1500 | H14: =E14*G14 | I14: R2 | J14: D2 | K14: Ремонт | L14: Э12
A15: 11 | B15: Ограничитель настенный (не в пол, D3) для Д-2 | C15: Morelli | D15: Morelli | E15: 1 | F15: шт | G15: 1100 | H15: =E15*G15 | I15: R2 | J15: D2 | K15: Ремонт | L15: Э12
A16: 12 | B16: Доводчик-демпфер от защемления для Д-2 | C16: — | D16: — | E16: 1 | F16: шт | G16: 2500 | H16: =E16*G16 | I16: R2 | J16: D2 | K16: Ремонт | L16: Э12
A17: 13 | B17: Дверь Д-3 (D3): полотно 700 × 2010 × 40, МДФ эмаль C1 филёнчатое, влагостойкое, коробка, наличники 70–80 с цоколем | C17: линии неоклассики под эмаль | D17: Софья / Волховец / ProfilDoors | E17: 1 | F17: компл | G17: 42000 | H17: =E17*G17 | I17: R5 | J17: D3; АР-08; M19 | K17: Ремонт | L17: Э12 | M17: проём 780 × 2180 (от пола коридора; порог-ступень +90, D20)
A18: 14 | B18: Петли скрытые 180° для Д-3 | C18: AGB Eclipse / Simonswerk Tectus-класс | D18: AGB | E18: 3 | F18: шт | G18: 2600 | H18: =E18*G18 | I18: R5 | J18: D3 | K18: Ремонт | L18: Э12
A19: 15 | B19: Ручка на розетке латунь сатин C8 для Д-3 | C19: Morelli / Fratelli Cattini | D19: Fratelli Cattini | E19: 1 | F19: компл | G19: 3800 | H19: =E19*G19 | I19: R5 | J19: D3 | K19: Ремонт | L19: Э12
A20: 16 | B20: Защёлка магнитная для Д-3 | C20: AGB Polaris | D20: AGB | E20: 1 | F20: шт | G20: 1500 | H20: =E20*G20 | I20: R5 | J20: D3 | K20: Ремонт | L20: Э12
A21: 17 | B21: WC-фиксатор с индикатором, латунь сатин, для Д-3 | C21: Fratelli Cattini | D21: Fratelli Cattini | E21: 1 | F21: шт | G21: 2600 | H21: =E21*G21 | I21: R5 | J21: D3 | K21: Ремонт | L21: Э12
A22: 18 | B22: Ограничитель настенный (не в пол, D3) для Д-3 | C22: Morelli | D22: Morelli | E22: 1 | F22: шт | G22: 1100 | H22: =E22*G22 | I22: R5 | J22: D3 | K22: Ремонт | L22: Э12
A23: 19 | B23: Переточная решётка в полотне для Д-3 | C23: — | D23: в цвет C1 | E23: 1 | F23: шт | G23: 1500 | H23: =E23*G23 | I23: R5 | J23: D3 | K23: Ремонт | L23: Э12
A24: 20 | B24: Дверь Д-4 (D4): полотно 700 × 2085 × 40, МДФ эмаль C1 филёнчатое, влагостойкое, коробка, наличники 70–80 с цоколем | C24: линии неоклассики под эмаль | D24: Софья / Волховец / ProfilDoors | E24: 1 | F24: компл | G24: 42000 | H24: =E24*G24 | I24: R6 | J24: D4; АР-08; M19 | K24: Ремонт | L24: Э12 | M24: проём 780 × 2180
A25: 21 | B25: Петли скрытые 180° для Д-4 | C25: AGB Eclipse / Simonswerk Tectus-класс | D25: AGB | E25: 3 | F25: шт | G25: 2600 | H25: =E25*G25 | I25: R6 | J25: D4 | K25: Ремонт | L25: Э12
A26: 22 | B26: Ручка на розетке латунь сатин C8 для Д-4 | C26: Morelli / Fratelli Cattini | D26: Fratelli Cattini | E26: 1 | F26: компл | G26: 3800 | H26: =E26*G26 | I26: R6 | J26: D4 | K26: Ремонт | L26: Э12
A27: 23 | B27: Защёлка магнитная для Д-4 | C27: AGB Polaris | D27: AGB | E27: 1 | F27: шт | G27: 1500 | H27: =E27*G27 | I27: R6 | J27: D4 | K27: Ремонт | L27: Э12
A28: 24 | B28: WC-фиксатор с индикатором, латунь сатин, для Д-4 | C28: Fratelli Cattini | D28: Fratelli Cattini | E28: 1 | F28: шт | G28: 2600 | H28: =E28*G28 | I28: R6 | J28: D4 | K28: Ремонт | L28: Э12
A29: 25 | B29: Ограничитель настенный (не в пол, D3) для Д-4 | C29: Morelli | D29: Morelli | E29: 1 | F29: шт | G29: 1100 | H29: =E29*G29 | I29: R6 | J29: D4 | K29: Ремонт | L29: Э12
A30: 26 | B30: Надпроёмная панель над D1 до +2750 (МДФ эмаль C1, в системе двери) | C30: — | D30: Софья / Волховец / ProfilDoors | E30: 1 | F30: шт | G30: 12000 | H30: =E30*G30 | I30: R1 | J30: D1; doors.json opening_clear; M19 | K30: Ремонт | L30: Э12
A31: 27 | B31: Наличник C1 изнутри входной двери ДВ-1 (комплект с цоколем) | C31: — | D31: Софья / Волховец | E31: 1 | F31: компл | G31: 8000 | H31: =E31*G31 | I31: R4 | J31: O5; ДВ-1 | K31: Ремонт | L31: Э12
B33: Итого по спецификации | H33: =SUM(H5:H31)
B34: в т.ч. «Ремонт» | H34: =SUMIF(K5:K31,"Ремонт",H5:H31)
B35: в т.ч. «Мебель+техника» | H35: =SUMIF(K5:K31,"Мебель+техника",H5:H31)

Sheet СП-05 Отделочные и черновые мат
A1: СП-05. Отделочные и черновые материалы (с запасами)
A2: Цены — ориентировочные для Санкт-Петербурга на 10.2026 (средний сегмент, розница/подрядчики), не являются офертой и подлежат проверке у поставщиков перед закупкой. Материалы — по диапазонам 02-concept/materials.json (price_ref) с поправкой на рост цен 1-го полугодия 2026 (INFOline: плитка +17 %, электрика +15 %, ЛКМ +10 %, напольные +10,5 %); расценки работ — калибровка по открытым прайсам СПб (поиск 2026-10-08, источники в 05-estimate/estimate.md).
A4: Поз. | B4: Наименование | C4: Артикул / пример | D4: Производитель | E4: Кол-во | F4: Ед. | G4: Цена ориент., ₽ | H4: Сумма, ₽ | I4: Помещение | J4: Ссылка (лист / id) | K4: Бюджет | L4: Этап сметы | M4: Примечание / расчёт кол-ва
A5: 1 | B5: Инженерная доска дуб 2-слойная 14–15 мм, ёлочка 90×600, ультраматовый лак, допуск на водяной ТП | C5: Coswick «Ёлочка» / Alpine Floor Villa Herringbone | D5: Coswick / Alpine Floor | E5: =CEILING(51.45*1.08,1.0) | F5: м² | G5: 7800 | H5: =E5*G5 | I5: R1, R2, R3, R4 | J5: floors oak_herringbone (R1 17,54, R2 11,87, R3 14,59, R4 7,45); M01; АР-10 | K5: Ремонт | L5: Э11 | M5: нетто 51.45 м² × 1.08 → упаковка 1.0 м²
A6: 2 | B6: Клей паркетный MS-полимер эластичный (1,2 кг/м²) | C6: Uzin MK 250 / Bostik Tarbicol MS | D6: Uzin / Bostik | E6: =CEILING(51.45*1.2,15) | F6: кг | G6: 700 | H6: =E6*G6 | I6: R1, R2, R3, R4 | J6: P-OAK; M01 | K6: Ремонт | L6: Э11
A7: 3 | B7: Грунт/ремонтный состав под клей (0,2 л/м²) и локальный ремонт стяжки | C7: Uzin PE 460 / Bostik | D7: Uzin | E7: 15 | F7: л | G7: 950 | H7: =E7*G7 | I7: R1, R2, R3, R4 | J7: P-OAK | K7: Ремонт | L7: Э11
A8: 4 | B8: LVT клеевой «ёлочка» в тон дуба C7, 33/42 кл., слой износа ≥ 0,55, допуск на ТП | C8: Alpine Floor Parquet LVT / Aquafloor Parquet Glue | D8: Alpine Floor | E8: =CEILING(6.47*1.08,0.5) | F8: м² | G8: 3300 | H8: =E8*G8 | I8: R7 | J8: floors lvt_herringbone; M28 | K8: Ремонт | L8: Э11 | M8: нетто 6.47 м² × 1.08 → упаковка 0.5 м²
A9: 5 | B9: Клей дисперсионный для LVT (0,35 кг/м²) | C9: Bostik / Forbo / Homakoll | D9: Homakoll | E9: 3 | F9: кг | G9: 450 | H9: =E9*G9 | I9: R7 | J9: P-BALC; M28 | K9: Ремонт | L9: Э11
A10: 6 | B10: Керамогранит 60×60 «светлый камень» R10 ректификат (вход) | C10: Kerama Marazzi / Italon / Estima | D10: Kerama Marazzi | E10: =CEILING(1.89*1.1,1.44) | F10: м² | G10: 3900 | H10: =E10*G10 | I10: R4 | J10: floors porcelain_60x60_hall; M16 | K10: Ремонт | L10: Э08 | M10: нетто 1.89 м² × 1.1 → упаковка 1.44 м²
A11: 7 | B11: Керамогранит 60×60 «светлый мрамор» R10 ректификат (ванная, постирочная) | C11: Italon Charme Evo / Kerama Marazzi | D11: Italon | E11: =CEILING(5.85*1.1,1.44) | F11: м² | G11: 4500 | H11: =E11*G11 | I11: R5, R6 | J11: floors porcelain_60x60_bath + _laundry; M20, M25 | K11: Ремонт | L11: Э08 | M11: нетто 5.85 м² × 1.1 → упаковка 1.44 м²
A12: 8 | B12: Керамогранит 60×120 «светлый мрамор» R10/B (пол душа, уклон к трапу) | C12: Italon Charme Evo (структ.) | D12: Italon | E12: =CEILING(0.71*1.15,1.44) | F12: м² | G12: 5900 | H12: =E12*G12 | I12: R5 | J12: floors porcelain_60x120_shower_R10B; M20 | K12: Ремонт | L12: Э08 | M12: нетто 0.71 м² × 1.15 → упаковка 1.44 м²
A13: 9 | B13: Керамогранит 60×120 «светлый мрамор» матовый — стены ванной (мокрые зоны до потолка + до +1280) и фартук кухни | C13: Italon Charme Evo / Kerama Marazzi | D13: Italon | E13: =CEILING(18.3*1.15,1.44) | F13: м² | G13: 5600 | H13: =E13*G13 | I13: R5, R3 | J13: walls tile_wet + tile_dry + tile_apron_porcelain; M21, M13; АР-13, АР-11 | K13: Ремонт | L13: Э08 | M13: нетто 18.3 м² × 1.15 → упаковка 1.44 м²
A14: 10 | B14: Плитка «кабанчик» матовая (фартук хозмойки) | C14: Kerama Marazzi «Метро» / Estima | D14: Kerama Marazzi | E14: =CEILING(0.77*1.1,1.0) | F14: м² | G14: 2600 | H14: =E14*G14 | I14: R6 | J14: walls tile_apron; M27; АР-14 | K14: Ремонт | L14: Э08 | M14: нетто 0.77 м² × 1.1 → упаковка 1.0 м²
A15: 11 | B15: Клей плиточный C2TE S1 для ТП и крупного формата (пол 7 кг/м², стены 6 кг/м²) | C15: Litokol Hyperflex K100 / Ceresit CM 17 | D15: Litokol | E15: =CEILING((8.45*7+19.07*6)/25,1) | F15: меш. 25 кг | G15: 1250 | H15: =E15*G15 | I15: R3–R6 | J15: floors/walls tile_* | K15: Ремонт | L15: Э08
A16: 12 | B16: Затирка эпоксидная (ванная, 0,35 кг/м²) | C16: Litokol Starlike EVO | D16: Litokol | E16: 7 | F16: кг | G16: 1900 | H16: =E16*G16 | I16: R5 | J16: M21 | K16: Ремонт | L16: Э08
A17: 13 | B17: Затирка цементная (прихожая, постирочная, фартуки, 0,3 кг/м²) | C17: Litokol Litochrom | D17: Litokol | E17: 3 | F17: кг | G17: 350 | H17: =E17*G17 | I17: R3, R4, R6 | J17: tile_* | K17: Ремонт | L17: Э08
A18: 14 | B18: Система выравнивания плитки (СВП: клипсы, клинья) | C18: — | D18: — | E18: 28 | F18: м² | G18: 120 | H18: =E18*G18 | I18: R3–R6 | J18: tile_* | K18: Ремонт | L18: Э08
A19: 15 | B19: Профиль латунь для плитки 10 мм (линия +1280 и обрамление ниш) | C19: Progress Profiles / Butech | D19: Progress Profiles | E19: 10.8 | F19: м | G19: 1500 | H19: =E19*G19 | I19: R5 | J19: walls tile_dry (Σ длин 5.57); ниши 3.3 м; M21 | K19: Ремонт | L19: Э08
A20: 16 | B20: Порог-ступень D3 из керамогранита 800×100×90 (изготовление) | C20: серия C9 | D20: мастерская | E20: 1 | F20: шт | G20: 4500 | H20: =E20*G20 | I20: R5 | J20: J5; узел 5; D20 | K20: Ремонт | L20: Э08
A21: 17 | B21: Порог-ограничитель D4 800×80×15 (керамогранит/камень, скругл.) | C21: — | D21: мастерская | E21: 1 | F21: шт | G21: 2500 | H21: =E21*G21 | I21: R6 | J21: J6; D4 | K21: Ремонт | L21: Э08
A22: 18 | B22: Гидроизоляция обмазочная 2-компонентная (2 слоя, 2,8 кг/м²; пол ванной — нижняя + основная) | C22: Mapei Mapelastic / Ceresit CL 51 | D22: Mapei | E22: =CEILING(26.56*2.8,1) | F22: кг | G22: 420 | H22: =E22*G22 | I22: R5, R6 | J22: floors waterproofing_floor ×(2 в R5) + waterproofing_walls = 26.56 м² | K22: Ремонт | L22: Э06
A23: 19 | B23: Ленты, углы, манжеты, фланец трапа (комплект на помещение) | C23: Mapei Mapeband | D23: Mapei | E23: 2 | F23: компл | G23: 6500 | H23: =E23*G23 | I23: R5, R6 | J23: узел 6 | K23: Ремонт | L23: Э06
A24: 20 | B24: ЦПС М300 (подиум ванной 78,5 мм, фибра) | C24: Каменный цветок / Knauf | D24: — | E24: =CEILING(5.1*0.0785*2000/40,1) | F24: меш. 40 кг | G24: 380 | H24: =E24*G24 | I24: R5 | J24: floors podium_screed_80; P-BATH | K24: Ремонт | L24: Э06
A25: 21 | B25: Сетка Вр4 50×50 + фибра + демпферная лента (подиум, стяжка балкона) | C25: — | D25: — | E25: 14 | F25: м² | G25: 380 | H25: =E25*G25 | I25: R5, R7 | J25: P-BATH, P-BALC; периметры R5 9.36 м, R7 10.67 м | K25: Ремонт | L25: Э06
A26: 22 | B26: Рамка-бортик U14 (ЦСП 20 / уголок нерж.) | C26: VK-C3 | D26: — | E26: 1 | F26: шт | G26: 2500 | H26: =E26*G26 | I26: R5 | J26: VK-C3; J7; узел 6 | K26: Ремонт | L26: Э06
A27: 23 | B27: XPS 300 кПа 50 мм (пол балкона) | C27: Пеноплэкс Комфорт / Технониколь Carbon | D27: Пеноплэкс | E27: 7.92 | F27: м² | G27: 650 | H27: =E27*G27 | I27: R7 | J27: floors xps50+screed55; P-BALC; D22 | K27: Ремонт | L27: Э06
A28: 24 | B28: Плёнка ПЭ 200 мкм (нахлёст 100, завод на стены) | C28: — | D28: — | E28: 9 | F28: м² | G28: 45 | H28: =E28*G28 | I28: R7 | J28: P-BALC | K28: Ремонт | L28: Э06
A29: 25 | B29: ЦПС М300 (стяжка балкона 55 мм) | C29: — | D29: — | E29: =CEILING(6.86*0.055*2000/40,1) | F29: меш. 40 кг | G29: 380 | H29: =E29*G29 | I29: R7 | J29: P-BALC | K29: Ремонт | L29: Э06
A30: 26 | B30: Самовыравнивающая смесь 10 мм по мату TP3 (16 кг/м²) | C30: Ceresit CN 175 / Knauf Боден | D30: Ceresit | E30: 5 | F30: меш. 25 кг | G30: 950 | H30: =E30*G30 | I30: R7 | J30: P-BALC | K30: Ремонт | L30: Э06
A31: 27 | B31: Остекление балкона тёплое ПВХ 70 мм, 2-камерный энергосберегающий стеклопакет, наружное стекло триплекс P2A, фурнитура с детским замком, отливы, подоконник | C31: VEKA / Exprof / Rehau-класс | D31: переработчик СПб | E31: 10.5 | F31: м² | G31: 21000 | H31: =E31*G31 | I31: R7 | J31: electrical.json balcony_heat_balance (остекление 10,5 м²); M32; №12 | K31: Ремонт | L31: Э03 | M31: поставка; монтаж — в работах
A32: 28 | B32: Оконный приточный клапан в раме (гигрорегулируемый) | C32: Aereco / Air-Box | D32: Aereco | E32: 2 | F32: шт | G32: 3500 | H32: =E32*G32 | I32: R7 | J32: SV1, SV2; ОВ-02 | K32: Ремонт | L32: Э03
A33: 29 | B33: Утеплитель PIR 50 фольгированный (парапеты, потолок балкона) | C33: Logicpir / Технониколь | D33: Технониколь | E33: 14.4 | F33: м² | G33: 1050 | H33: =E33*G33 | I33: R7 | J33: walls gvl+paint_c6 7.05 + ceilings R7 6.08; M29, M30 | K33: Ремонт | L33: Э03
A34: 30 | B34: Лента алюминиевая, пароизоляция примыканий, пена | C34: — | D34: — | E34: 1 | F34: компл | G34: 4500 | H34: =E34*G34 | I34: R7 | J34: M29 | K34: Ремонт | L34: Э03
A35: 31 | B35: ГВЛ 12,5 (обшивка парапетов) 2500×1200 | C35: Knauf ГВЛ | D35: Knauf | E35: 3 | F35: лист | G35: 780 | H35: =E35*G35 | I35: R7 | J35: walls gvl+paint_c6 | K35: Ремонт | L35: Э03
A36: 32 | B36: Каркас для обшивки парапетов (ПП 60/27, ПН, подвесы, крепёж) | C36: Knauf | D36: Knauf | E36: 8 | F36: м² | G36: 450 | H36: =E36*G36 | I36: R7 | J36: walls gvl+paint_c6 | K36: Ремонт | L36: Э03
A37: 33 | B37: ПГП полнотелая 667×500×100 (NW1) | C37: Волма / Knauf | D37: Волма | E37: 16 | F37: шт | G37: 520 | H37: =E37*G37 | I37: R1/R3 | J37: NW1 4.87 м²; planning.json new_walls | K37: Ремонт | L37: Э02
A38: 34 | B38: ПГП полнотелая 667×500×80 (NW4, добор D1) | C38: Волма / Knauf | D38: Волма | E38: 7 | F38: шт | G38: 400 | H38: =E38*G38 | I38: R2/R4, R1 | J38: NW4 1.66 м² (за вычетом проёма D2) + добор 199 0.54 м² | K38: Ремонт | L38: Э02
A39: 35 | B39: ПГП гидрофобизированная 667×500×80 (NW8, NW9) | C39: Волма / Knauf | D39: Волма | E39: 7 | F39: шт | G39: 450 | H39: =E39*G39 | I39: R5, R6 | J39: NW8 1.01 + NW9 1.13 м² | K39: Ремонт | L39: Э02
A40: 36 | B40: Клей гипсовый монтажный для ПГП (2 кг/м²) + ГКЛ на клей NW1 | C40: Волма Монтаж / Knauf Перлфикс | D40: Волма | E40: 2 | F40: меш. 30 кг | G40: 620 | H40: =E40*G40 | I40: — | J40: new_walls | K40: Ремонт | L40: Э02
A41: 37 | B41: Лента демпферная 10 мм + скобы/гибкие связи (без дюбелей в пол, D3) | C41: — | D41: — | E41: 31 | F41: м | G41: 120 | H41: =E41*G41 | I41: — | J41: new_walls: периметры NW1, NW4, NW8, NW9 = 30.18 м | K41: Ремонт | L41: Э02
...

Sheet СП-04.2 Тёплые полы (электро) и
A1: СП-04.2. Тёплые полы (электро) и ОВ
